Workbook

Sheet 대시보드
A1: 팀별 현황 대시보드
A2: 여력 · 수주 달성 현황 요약 | 기준월은 팀별분석 시트 B5에서 설정합니다
A4: 전사 평균 가동률 | C4: 연간 여유 M/M | E4: 확정 수주 | G4: 귀속 이윤 | I4: 수주 달성률 | K4: 기간 진도율 | M4: 이윤 달성률
A5: =IF(팀별분석!D18=0,"",팀별분석!B69/팀별분석!D18) -> 0.81699346 | C5: =팀별분석!D18-팀별분석!B69 -> 28 | E5: =팀별분석!D69 -> 1640000000 | G5: =팀별분석!E69 -> 448000000 | I5: =팀별분석!J69 -> 0.93181818 | K5: =팀별분석!$B$6 -> 0.66666667 | M5: =팀별분석!O69
A8: 팀별 현황
A9: =IF(팀별분석!A10="","(빈 슬롯)",팀별분석!A10) -> 사업운영팀 기획1파트 | G9: =IF(팀별분석!A11="","(빈 슬롯)",팀별분석!A11) -> 사업운영팀 기획2파트
A10: 가동률 | C10: =IF(팀별분석!A10="","",팀별분석!B74) -> 1.0372549 | G10: 가동률 | I10: =IF(팀별분석!A11="","",팀별분석!B75) -> 0.6495098
A11: 연간 여유 M/M | C11: =IF(팀별분석!A10="","",팀별분석!N49) -> -1.9 | G11: 연간 여유 M/M | I11: =IF(팀별분석!A11="","",팀별분석!N50) -> 14.3
A12: 수주 달성률 | C12: =IF(OR(팀별분석!A10="",팀별분석!I61=0),"",팀별분석!J61) -> 0.99 | G12: 수주 달성률 | I12: =IF(OR(팀별분석!A11="",팀별분석!I62=0),"",팀별분석!J62) -> 0.86
A13: 진도 차이 | C13: =IF(OR(팀별분석!A10="",팀별분석!I61=0),"",팀별분석!L61) -> 0.32333333 | G13: 진도 차이 | I13: =IF(OR(팀별분석!A11="",팀별분석!I62=0),"",팀별분석!L62) -> 0.19333333
A14: =IF(팀별분석!A10="","",팀별분석!I74) -> 과부하 | D14: =IF(팀별분석!A10="","",팀별분석!J74) -> 진도 앞섬 | G14: =IF(팀별분석!A11="","",팀별분석!I75) -> 여력 있음 | J14: =IF(팀별분석!A11="","",팀별분석!J75) -> 진도 앞섬
A16: =IF(팀별분석!A12="","(빈 슬롯)",팀별분석!A12) -> 신사업팀 | G16: =IF(팀별분석!A13="","(빈 슬롯)",팀별분석!A13) -> 경영본부 사업기획실
A17: 가동률 | C17: =IF(팀별분석!A12="","",팀별분석!B76) -> 0.58823529 | G17: 가동률 | I17: =IF(팀별분석!A13="","",팀별분석!B77) -> 0.90196078
A18: 연간 여유 M/M | C18: =IF(팀별분석!A12="","",팀별분석!N51) -> 12.6 | G18: 연간 여유 M/M | I18: =IF(팀별분석!A13="","",팀별분석!N52) -> 3
A19: 수주 달성률 | C19: =IF(OR(팀별분석!A12="",팀별분석!I63=0),"",팀별분석!J63) -> 0.51243243 | G19: 수주 달성률 | I19: =IF(OR(팀별분석!A13="",팀별분석!I64=0),"",팀별분석!J64) -> 9.1891892
A20: 진도 차이 | C20: =IF(OR(팀별분석!A12="",팀별분석!I63=0),"",팀별분석!L63) -> -0.15423423 | G20: 진도 차이 | I20: =IF(OR(팀별분석!A13="",팀별분석!I64=0),"",팀별분석!L64) -> 8.5225225
A21: =IF(팀별분석!A12="","",팀별분석!I76) -> 여력 있음 | D21: =IF(팀별분석!A12="","",팀별분석!J76) -> 진도 지연 | G21: =IF(팀별분석!A13="","",팀별분석!I77) -> 여유 없음 | J21: =IF(팀별분석!A13="","",팀별분석!J77) -> 진도 앞섬
A23: =IF(팀별분석!A14="","(빈 슬롯)",팀별분석!A14) -> (빈 슬롯) | G23: =IF(팀별분석!A15="","(빈 슬롯)",팀별분석!A15) -> (빈 슬롯)
A24: 가동률 | C24: =IF(팀별분석!A14="","",팀별분석!B78) | G24: 가동률 | I24: =IF(팀별분석!A15="","",팀별분석!B79)
A25: 연간 여유 M/M | C25: =IF(팀별분석!A14="","",팀별분석!N53) | G25: 연간 여유 M/M | I25: =IF(팀별분석!A15="","",팀별분석!N54)
A26: 수주 달성률 | C26: =IF(OR(팀별분석!A14="",팀별분석!I65=0),"",팀별분석!J65) | G26: 수주 달성률 | I26: =IF(OR(팀별분석!A15="",팀별분석!I66=0),"",팀별분석!J66)
A27: 진도 차이 | C27: =IF(OR(팀별분석!A14="",팀별분석!I65=0),"",팀별분석!L65) | G27: 진도 차이 | I27: =IF(OR(팀별분석!A15="",팀별분석!I66=0),"",팀별분석!L66)
A28: =IF(팀별분석!A14="","",팀별분석!I78) | D28: =IF(팀별분석!A14="","",팀별분석!J78) | G28: =IF(팀별분석!A15="","",팀별분석!I79) | J28: =IF(팀별분석!A15="","",팀별분석!J79)
A30: =IF(팀별분석!A16="","(빈 슬롯)",팀별분석!A16) -> (빈 슬롯) | G30: =IF(팀별분석!A17="","(빈 슬롯)",팀별분석!A17) -> (빈 슬롯)
A31: 가동률 | C31: =IF(팀별분석!A16="","",팀별분석!B80) | G31: 가동률 | I31: =IF(팀별분석!A17="","",팀별분석!B81)
A32: 연간 여유 M/M | C32: =IF(팀별분석!A16="","",팀별분석!N55) | G32: 연간 여유 M/M | I32: =IF(팀별분석!A17="","",팀별분석!N56)
A33: 수주 달성률 | C33: =IF(OR(팀별분석!A16="",팀별분석!I67=0),"",팀별분석!J67) | G33: 수주 달성률 | I33: =IF(OR(팀별분석!A17="",팀별분석!I68=0),"",팀별분석!J68)
A34: 진도 차이 | C34: =IF(OR(팀별분석!A16="",팀별분석!I67=0),"",팀별분석!L67) | G34: 진도 차이 | I34: =IF(OR(팀별분석!A17="",팀별분석!I68=0),"",팀별분석!L68)
A35: =IF(팀별분석!A16="","",팀별분석!I80) | D35: =IF(팀별분석!A16="","",팀별분석!J80) | G35: =IF(팀별분석!A17="","",팀별분석!I81) | J35: =IF(팀별분석!A17="","",팀별분석!J81)
A38: 추이 · 비교
A85: ※ '여력 있음' + '진도 지연'이 겹치는 팀이 업무 재배분 1순위입니다.
A86: ※ 팀을 추가하려면 팀별분석 시트 ① 팀 구성의 빈 슬롯에 팀명·인원수·목표만 입력하세요. 이 화면에 자동으로 나타납니다.
A87: ※ 자세한 월별 수치는 상세현황 시트를, 원본 데이터는 사업정보·월간투입 시트를 보세요.

Sheet 사업정보
A1: 사업 정보 — 예산 · 기간 · 이윤
A2: 파란색 셀만 입력합니다. 수주가 확정된 사업만 등록하세요. 한 사업에 여러 팀이 붙어도 한 줄만 만들면 됩니다.
A3: 이윤은 견적서상 이윤을 금액으로 입력합니다. 운영·지원 업무도 한 줄씩 만들되 예산과 이윤은 비워 두세요.
A5: 사업 / 업무명 | B5: 구분 | C5: 시작월 | D5: 종료월 | E5: 기간 (개월) | F5: 예산 (원) | G5: 이윤 (원) | H5: 이윤율 | I5: 총 투입 M/M | J5: M/M당 예산 (원) | K5: M/M당 이윤 (원)
A6: 차세대 ERP 구축 | B6: 사업 | C6: 46023 | D6: 46174 | E6: =IF(OR($C6="",$D6=""),"",(YEAR($D6)-YEAR($C6))*12+MONTH($D6)-MONTH($C6)+1) -> 6 | F6: 420000000 | G6: 126000000 | H6: =IF(OR($F6="",$F6=0),"",$G6/$F6) -> 0.3 | I6: =IF($A6="",0,SUMIF(월간투입!$C$8:$C$127,$A6,월간투입!$Q$8:$Q$127)) -> 10.3 | J6: =IF(OR($A6="",$I6=0,$F6=""),"",$F6/$I6) -> 40776699 | K6: =IF(OR($A6="",$I6=0,$G6=""),"",$G6/$I6) -> 12233010
A7: 하반기 고도화 PJT | B7: 사업 | C7: 46204 | D7: 46357 | E7: =IF(OR($C7="",$D7=""),"",(YEAR($D7)-YEAR($C7))*12+MONTH($D7)-MONTH($C7)+1) -> 6 | F7: 260000000 | G7: 70000000 | H7: =IF(OR($F7="",$F7=0),"",$G7/$F7) -> 0.26923077 | I7: =IF($A7="",0,SUMIF(월간투입!$C$8:$C$127,$A7,월간투입!$Q$8:$Q$127)) -> 8.4 | J7: =IF(OR($A7="",$I7=0,$F7=""),"",$F7/$I7) -> 30952381 | K7: =IF(OR($A7="",$I7=0,$G7=""),"",$G7/$I7) -> 8333333.3
A8: 채널 개편 PJT | B8: 사업 | C8: 46023 | D8: 46204 | E8: =IF(OR($C8="",$D8=""),"",(YEAR($D8)-YEAR($C8))*12+MONTH($D8)-MONTH($C8)+1) -> 7 | F8: 310000000 | G8: 96000000 | H8: =IF(OR($F8="",$F8=0),"",$G8/$F8) -> 0.30967742 | I8: =IF($A8="",0,SUMIF(월간투입!$C$8:$C$127,$A8,월간투입!$Q$8:$Q$127)) -> 9.6 | J8: =IF(OR($A8="",$I8=0,$F8=""),"",$F8/$I8) -> 32291667 | K8: =IF(OR($A8="",$I8=0,$G8=""),"",$G8/$I8) -> 10000000
A9: 물류 시스템 고도화 | B9: 사업 | C9: 46082 | D9: 46204 | E9: =IF(OR($C9="",$D9=""),"",(YEAR($D9)-YEAR($C9))*12+MONTH($D9)-MONTH($C9)+1) -> 5 | F9: 280000000 | G9: 78000000 | H9: =IF(OR($F9="",$F9=0),"",$G9/$F9) -> 0.27857143 | I9: =IF($A9="",0,SUMIF(월간투입!$C$8:$C$127,$A9,월간투입!$Q$8:$Q$127)) -> 10 | J9: =IF(OR($A9="",$I9=0,$F9=""),"",$F9/$I9) -> 28000000 | K9: =IF(OR($A9="",$I9=0,$G9=""),"",$G9/$I9) -> 7800000
A10: 데이터 표준화 PJT | B10: 사업 | C10: 46023 | D10: 46174 | E10: =IF(OR($C10="",$D10=""),"",(YEAR($D10)-YEAR($C10))*12+MONTH($D10)-MONTH($C10)+1) -> 6 | F10: 150000000 | G10: 38000000 | H10: =IF(OR($F10="",$F10=0),"",$G10/$F10) -> 0.25333333 | I10: =IF($A10="",0,SUMIF(월간투입!$C$8:$C$127,$A10,월간투입!$Q$8:$Q$127)) -> 9.6 | J10: =IF(OR($A10="",$I10=0,$F10=""),"",$F10/$I10) -> 15625000 | K10: =IF(OR($A10="",$I10=0,$G10=""),"",$G10/$I10) -> 3958333.3
A11: 신규 사업 타당성 검토 | B11: 사업 | C11: 46023 | D11: 46113 | E11: =IF(OR($C11="",$D11=""),"",(YEAR($D11)-YEAR($C11))*12+MONTH($D11)-MONTH($C11)+1) -> 4 | F11: 60000000 | G11: 12000000 | H11: =IF(OR($F11="",$F11=0),"",$G11/$F11) -> 0.2 | I11: =IF($A11="",0,SUMIF(월간투입!$C$8:$C$127,$A11,월간투입!$Q$8:$Q$127)) -> 4.4 | J11: =IF(OR($A11="",$I11=0,$F11=""),"",$F11/$I11) -> 13636364 | K11: =IF(OR($A11="",$I11=0,$G11=""),"",$G11/$I11) -> 2727272.7
A12: 파트너십 발굴 | B12: 사업 | C12: 46023 | D12: 46357 | E12: =IF(OR($C12="",$D12=""),"",(YEAR($D12)-YEAR($C12))*12+MONTH($D12)-MONTH($C12)+1) -> 12 | F12: 90000000 | G12: 18000000 | H12: =IF(OR($F12="",$F12=0),"",$G12/$F12) -> 0.2 | I12: =IF($A12="",0,SUMIF(월간투입!$C$8:$C$127,$A12,월간투입!$Q$8:$Q$127)) -> 14.8 | J12: =IF(OR($A12="",$I12=0,$F12=""),"",$F12/$I12) -> 6081081.1 | K12: =IF(OR($A12="",$I12=0,$G12=""),"",$G12/$I12) -> 1216216.2
A13: 중장기 전략 수립 | B13: 사업 | C13: 46023 | D13: 46357 | E13: =IF(OR($C13="",$D13=""),"",(YEAR($D13)-YEAR($C13))*12+MONTH($D13)-MONTH($C13)+1) -> 12 | F13: 70000000 | G13: 10000000 | H13: =IF(OR($F13="",$F13=0),"",$G13/$F13) -> 0.14285714 | I13: =IF($A13="",0,SUMIF(월간투입!$C$8:$C$127,$A13,월간투입!$Q$8:$Q$127)) -> 10.8 | J13: =IF(OR($A13="",$I13=0,$F13=""),"",$F13/$I13) -> 6481481.5 | K13: =IF(OR($A13="",$I13=0,$G13=""),"",$G13/$I13) -> 925925.93
A14: 월간 실적보고 운영 | B14: 운영 | E14: =IF(OR($C14="",$D14=""),"",(YEAR($D14)-YEAR($C14))*12+MONTH($D14)-MONTH($C14)+1) | H14: =IF(OR($F14="",$F14=0),"",$G14/$F14) | I14: =IF($A14="",0,SUMIF(월간투입!$C$8:$C$127,$A14,월간투입!$Q$8:$Q$127)) -> 2.4 | J14: =IF(OR($A14="",$I14=0,$F14=""),"",$F14/$I14) | K14: =IF(OR($A14="",$I14=0,$G14=""),"",$G14/$I14)
A15: 파트 상시 운영업무 | B15: 운영 | E15: =IF(OR($C15="",$D15=""),"",(YEAR($D15)-YEAR($C15))*12+MONTH($D15)-MONTH($C15)+1) | H15: =IF(OR($F15="",$F15=0),"",$G15/$F15) | I15: =IF($A15="",0,SUMIF(월간투입!$C$8:$C$127,$A15,월간투입!$Q$8:$Q$127)) -> 12 | J15: =IF(OR($A15="",$I15=0,$F15=""),"",$F15/$I15) | K15: =IF(OR($A15="",$I15=0,$G15=""),"",$G15/$I15)
A16: 정산·계약 운영 | B16: 운영 | E16: =IF(OR($C16="",$D16=""),"",(YEAR($D16)-YEAR($C16))*12+MONTH($D16)-MONTH($C16)+1) | H16: =IF(OR($F16="",$F16=0),"",$G16/$F16) | I16: =IF($A16="",0,SUMIF(월간투입!$C$8:$C$127,$A16,월간투입!$Q$8:$Q$127)) -> 6 | J16: =IF(OR($A16="",$I16=0,$F16=""),"",$F16/$I16) | K16: =IF(OR($A16="",$I16=0,$G16=""),"",$G16/$I16)
A17: 유지보수 대응 | B17: 운영 | E17: =IF(OR($C17="",$D17=""),"",(YEAR($D17)-YEAR($C17))*12+MONTH($D17)-MONTH($C17)+1) | H17: =IF(OR($F17="",$F17=0),"",$G17/$F17) | I17: =IF($A17="",0,SUMIF(월간투입!$C$8:$C$127,$A17,월간투입!$Q$8:$Q$127)) -> 3.3 | J17: =IF(OR($A17="",$I17=0,$F17=""),"",$F17/$I17) | K17: =IF(OR($A17="",$I17=0,$G17=""),"",$G17/$I17)
A18: 경영실적 분석 운영 | B18: 운영 | E18: =IF(OR($C18="",$D18=""),"",(YEAR($D18)-YEAR($C18))*12+MONTH($D18)-MONTH($C18)+1) | H18: =IF(OR($F18="",$F18=0),"",$G18/$F18) | I18: =IF($A18="",0,SUMIF(월간투입!$C$8:$C$127,$A18,월간투입!$Q$8:$Q$127)) -> 6 | J18: =IF(OR($A18="",$I18=0,$F18=""),"",$F18/$I18) | K18: =IF(OR($A18="",$I18=0,$G18=""),"",$G18/$I18)
A19: 신규 제안 지원 | B19: 지원 | E19: =IF(OR($C19="",$D19=""),"",(YEAR($D19)-YEAR($C19))*12+MONTH($D19)-MONTH($C19)+1) | H19: =IF(OR($F19="",$F19=0),"",$G19/$F19) | I19: =IF($A19="",0,SUMIF(월간투입!$C$8:$C$127,$A19,월간투입!$Q$8:$Q$127)) -> 4.8 | J19: =IF(OR($A19="",$I19=0,$F19=""),"",$F19/$I19) | K19: =IF(OR($A19="",$I19=0,$G19=""),"",$G19/$I19)
A20: 운영 이관 지원 | B20: 지원 | E20: =IF(OR($C20="",$D20=""),"",(YEAR($D20)-YEAR($C20))*12+MONTH($D20)-MONTH($C20)+1) | H20: =IF(OR($F20="",$F20=0),"",$G20/$F20) | I20: =IF($A20="",0,SUMIF(월간투입!$C$8:$C$127,$A20,월간투입!$Q$8:$Q$127)) -> 3 | J20: =IF(OR($A20="",$I20=0,$F20=""),"",$F20/$I20) | K20: =IF(OR($A20="",$I20=0,$G20=""),"",$G20/$I20)
A21: 시장조사 | B21: 지원 | E21: =IF(OR($C21="",$D21=""),"",(YEAR($D21)-YEAR($C21))*12+MONTH($D21)-MONTH($C21)+1) | H21: =IF(OR($F21="",$F21=0),"",$G21/$F21) | I21: =IF($A21="",0,SUMIF(월간투입!$C$8:$C$127,$A21,월간투입!$Q$8:$Q$127)) -> 2.4 | J21: =IF(OR($A21="",$I21=0,$F21=""),"",$F21/$I21) | K21: =IF(OR($A21="",$I21=0,$G21=""),"",$G21/$I21)
A22: 전사 예산 수립 지원 | B22: 지원 | E22: =IF(OR($C22="",$D22=""),"",(YEAR($D22)-YEAR($C22))*12+MONTH($D22)-MONTH($C22)+1) | H22: =IF(OR($F22="",$F22=0),"",$G22/$F22) | I22: =IF($A22="",0,SUMIF(월간투입!$C$8:$C$127,$A22,월간투입!$Q$8:$Q$127)) -> 6 | J22: =IF(OR($A22="",$I22=0,$F22=""),"",$F22/$I22) | K22: =IF(OR($A22="",$I22=0,$G22=""),"",$G22/$I22)
A23: 이사회 보고 지원 | B23: 지원 | E23: =IF(OR($C23="",$D23=""),"",(YEAR($D23)-YEAR($C23))*12+MONTH($D23)-MONTH($C23)+1) | H23: =IF(OR($F23="",$F23=0),"",$G23/$F23) | I23: =IF($A23="",0,SUMIF(월간투입!$C$8:$C$127,$A23,월간투입!$Q$8:$Q$127)) -> 1.2 | J23: =IF(OR($A23="",$I23=0,$F23=""),"",$F23/$I23) | K23: =IF(OR($A23="",$I23=0,$G23=""),"",$G23/$I23)
E24: =IF(OR($C24="",$D24=""),"",(YEAR($D24)-YEAR($C24))*12+MONTH($D24)-MONTH($C24)+1) | H24: =IF(OR($F24="",$F24=0),"",$G24/$F24) | I24: =IF($A24="",0,SUMIF(월간투입!$C$8:$C$127,$A24,월간투입!$Q$8:$Q$127)) -> 0 | J24: =IF(OR($A24="",$I24=0,$F24=""),"",$F24/$I24) | K24: =IF(OR($A24="",$I24=0,$G24=""),"",$G24/$I24)
E25: =IF(OR($C25="",$D25=""),"",(YEAR($D25)-YEAR($C25))*12+MONTH($D25)-MONTH($C25)+1) | H25: =IF(OR($F25="",$F25=0),"",$G25/$F25) | I25: =IF($A25="",0,SUMIF(월간투입!$C$8:$C$127,$A25,월간투입!$Q$8:$Q$127)) -> 0 | J25: =IF(OR($A25="",$I25=0,$F25=""),"",$F25/$I25) | K25: =IF(OR($A25="",$I25=0,$G25=""),"",$G25/$I25)
E26: =IF(OR($C26="",$D26=""),"",(YEAR($D26)-YEAR($C26))*12+MONTH($D26)-MONTH($C26)+1) | H26: =IF(OR($F26="",$F26=0),"",$G26/$F26) | I26: =IF($A26="",0,SUMIF(월간투입!$C$8:$C$127,$A26,월간투입!$Q$8:$Q$127)) -> 0 | J26: =IF(OR($A26="",$I26=0,$F26=""),"",$F26/$I26) | K26: =IF(OR($A26="",$I26=0,$G26=""),"",$G26/$I26)
E27: =IF(OR($C27="",$D27=""),"",(YEAR($D27)-YEAR($C27))*12+MONTH($D27)-MONTH($C27)+1) | H27: =IF(OR($F27="",$F27=0),"",$G27/$F27) | I27: =IF($A27="",0,SUMIF(월간투입!$C$8:$C$127,$A27,월간투입!$Q$8:$Q$127)) -> 0 | J27: =IF(OR($A27="",$I27=0,$F27=""),"",$F27/$I27) | K27: =IF(OR($A27="",$I27=0,$G27=""),"",$G27/$I27)
E28: =IF(OR($C28="",$D28=""),"",(YEAR($D28)-YEAR($C28))*12+MONTH($D28)-MONTH($C28)+1) | H28: =IF(OR($F28="",$F28=0),"",$G28/$F28) | I28: =IF($A28="",0,SUMIF(월간투입!$C$8:$C$127,$A28,월간투입!$Q$8:$Q$127)) -> 0 | J28: =IF(OR($A28="",$I28=0,$F28=""),"",$F28/$I28) | K28: =IF(OR($A28="",$I28=0,$G28=""),"",$G28/$I28)
E29: =IF(OR($C29="",$D29=""),"",(YEAR($D29)-YEAR($C29))*12+MONTH($D29)-MONTH($C29)+1) | H29: =IF(OR($F29="",$F29=0),"",$G29/$F29) | I29: =IF($A29="",0,SUMIF(월간투입!$C$8:$C$127,$A29,월간투입!$Q$8:$Q$127)) -> 0 | J29: =IF(OR($A29="",$I29=0,$F29=""),"",$F29/$I29) | K29: =IF(OR($A29="",$I29=0,$G29=""),"",$G29/$I29)
E30: =IF(OR($C30="",$D30=""),"",(YEAR($D30)-YEAR($C30))*12+MONTH($D30)-MONTH($C30)+1) | H30: =IF(OR($F30="",$F30=0),"",$G30/$F30) | I30: =IF($A30="",0,SUMIF(월간투입!$C$8:$C$127,$A30,월간투입!$Q$8:$Q$127)) -> 0 | J30: =IF(OR($A30="",$I30=0,$F30=""),"",$F30/$I30) | K30: =IF(OR($A30="",$I30=0,$G30=""),"",$G30/$I30)
E31: =IF(OR($C31="",$D31=""),"",(YEAR($D31)-YEAR($C31))*12+MONTH($D31)-MONTH($C31)+1) | H31: =IF(OR($F31="",$F31=0),"",$G31/$F31) | I31: =IF($A31="",0,SUMIF(월간투입!$C$8:$C$127,$A31,월간투입!$Q$8:$Q$127)) -> 0 | J31: =IF(OR($A31="",$I31=0,$F31=""),"",$F31/$I31) | K31: =IF(OR($A31="",$I31=0,$G31=""),"",$G31/$I31)
E32: =IF(OR($C32="",$D32=""),"",(YEAR($D32)-YEAR($C32))*12+MONTH($D32)-MONTH($C32)+1) | H32: =IF(OR($F32="",$F32=0),"",$G32/$F32) | I32: =IF($A32="",0,SUMIF(월간투입!$C$8:$C$127,$A32,월간투입!$Q$8:$Q$127)) -> 0 | J32: =IF(OR($A32="",$I32=0,$F32=""),"",$F32/$I32) | K32: =IF(OR($A32="",$I32=0,$G32=""),"",$G32/$I32)
E33: =IF(OR($C33="",$D33=""),"",(YEAR($D33)-YEAR($C33))*12+MONTH($D33)-MONTH($C33)+1) | H33: =IF(OR($F33="",$F33=0),"",$G33/$F33) | I33: =IF($A33="",0,SUMIF(월간투입!$C$8:$C$127,$A33,월간투입!$Q$8:$Q$127)) -> 0 | J33: =IF(OR($A33="",$I33=0,$F33=""),"",$F33/$I33) | K33: =IF(OR($A33="",$I33=0,$G33=""),"",$G33/$I33)
E34: =IF(OR($C34="",$D34=""),"",(YEAR($D34)-YEAR($C34))*12+MONTH($D34)-MONTH($C34)+1) | H34: =IF(OR($F34="",$F34=0),"",$G34/$F34) | I34: =IF($A34="",0,SUMIF(월간투입!$C$8:$C$127,$A34,월간투입!$Q$8:$Q$127)) -> 0 | J34: =IF(OR($A34="",$I34=0,$F34=""),"",$F34/$I34) | K34: =IF(OR($A34="",$I34=0,$G34=""),"",$G34/$I34)
E35: =IF(OR($C35="",$D35=""),"",(YEAR($D35)-YEAR($C35))*12+MONTH($D35)-MONTH($C35)+1) | H35: =IF(OR($F35="",$F35=0),"",$G35/$F35) | I35: =IF($A35="",0,SUMIF(월간투입!$C$8:$C$127,$A35,월간투입!$Q$8:$Q$127)) -> 0 | J35: =IF(OR($A35="",$I35=0,$F35=""),"",$F35/$I35) | K35: =IF(OR($A35="",$I35=0,$G35=""),"",$G35/$I35)
A36: 합계 | F36: =SUM(F6:F35) -> 1640000000 | G36: =SUM(G6:G35) -> 448000000 | H36: =IF(F36=0,"",G36/F36) -> 0.27317073 | I36: =SUM(I6:I35) -> 125
A38: ※ 회색 배경 18개 행(6~23행)은 입력 예시입니다. 행 전체를 삭제하고 실제 데이터를 넣으세요.
A39: ※ 수주 확정 사업만 등록합니다. 제안 중이거나 예정인 건은 넣지 마세요. 달성률이 왜곡됩니다.
A40: ※ 이윤은 견적서상 이윤(금액)입니다. 이윤율과 M/M당 지표는 자동 계산됩니다.
A41: ※ 총 투입 M/M은 월간투입 시트에서 자동으로 채워집니다.

Sheet 월간투입
A1: 월간 투입률 입력
A2: 담당자와 사업명은 드롭다운에서 고르고, 월별 투입률만 입력합니다. 팀은 자동으로 붙습니다.
A3: ★ 투입률은 '정규 근무시간(8시간) 대비 실제로 쓴 비율'입니다. 야근·주말 근무도 그대로 반영해 주세요. 예) 정규시간을 다 쓰고 2시간 더 했으면 합계 125%. 합계가 100%를 넘어도 됩니다.
A5: 기준 시작월 | B5: 46023 | C5: ← 이 값만 바꾸면 모든 시트의 월 헤더가 함께 이동합니다.
A7: 팀 | B7: 담당자 | C7: 사업 / 업무명 | D7: 구분 | E7: =$B$5 -> 46023 | F7: =EDATE(E$7,1) -> 46054 | G7: =EDATE(F$7,1) -> 46082 | H7: =EDATE(G$7,1) -> 46113 | I7: =EDATE(H$7,1) -> 46143 | J7: =EDATE(I$7,1) -> 46174 | K7: =EDATE(J$7,1) -> 46204 | L7: =EDATE(K$7,1) -> 46235 | M7: =EDATE(L$7,1) -> 46266 | ... P7: =EDATE(O$7,1) -> 46357 | Q7: 합계 M/M | R7: 귀속 예산 (원) | S7: 귀속 이윤 (원)
A8: =IF($B8="","",IFERROR(INDEX(팀별분석!$R$9:$R$48,MATCH($B8,팀별분석!$Q$9:$Q$48,0)),"명단확인")) -> 사업운영팀 기획1파트 | B8: 홍길동 | C8: 차세대 ERP 구축 | D8: =IF($C8="","",IFERROR(INDEX(사업정보!$B$6:$B$35,MATCH($C8,사업정보!$A$6:$A$35,0)),"사업명확인")) -> 사업 | E8: 0.7 | F8: 0.7 | G8: 0.7 | H8: 0.6 | I8: 0.4 | Q8: =IF($B8="",0,SUM(E8:P8)) -> 3.1 | R8: =IF($B8="",0,IFERROR(Q8*INDEX(사업정보!$F$6:$F$35,MATCH($C8,사업정보!$A$6:$A$35,0))/INDEX(사업정보!$I$6:$I$35,MATCH($C8,사업정보!$A$6:$A$35,0)),0)) -> 1.2640777e+08 | S8: =IF($B8="",0,IFERROR(Q8*INDEX(사업정보!$G$6:$G$35,MATCH($C8,사업정보!$A$6:$A$35,0))/INDEX(사업정보!$I$6:$I$35,MATCH($C8,사업정보!$A$6:$A$35,0)),0)) -> 37922330
A9: =IF($B9="","",IFERROR(INDEX(팀별분석!$R$9:$R$48,MATCH($B9,팀별분석!$Q$9:$Q$48,0)),"명단확인")) -> 사업운영팀 기획1파트 | B9: 홍길동 | C9: 월간 실적보고 운영 | D9: =IF($C9="","",IFERROR(INDEX(사업정보!$B$6:$B$35,MATCH($C9,사업정보!$A$6:$A$35,0)),"사업명확인")) -> 운영 | E9: 0.2 | F9: 0.2 | G9: 0.2 | H9: 0.2 | I9: 0.2 | J9: 0.2 | K9: 0.2 | L9: 0.2 | M9: 0.2 | N9: 0.2 | O9: 0.2 | P9: 0.2 | Q9: =IF($B9="",0,SUM(E9:P9)) -> 2.4 | R9: =IF($B9="",0,IFERROR(Q9*INDEX(사업정보!$F$6:$F$35,MATCH($C9,사업정보!$A$6:$A$35,0))/INDEX(사업정보!$I$6:$I$35,MATCH($C9,사업정보!$A$6:$A$35,0)),0)) -> 0 | S9: =IF($B9="",0,IFERROR(Q9*INDEX(사업정보!$G$6:$G$35,MATCH($C9,사업정보!$A$6:$A$35,0))/INDEX(사업정보!$I$6:$I$35,MATCH($C9,사업정보!$A$6:$A$35,0)),0)) -> 0
A10: =IF($B10="","",IFERROR(INDEX(팀별분석!$R$9:$R$48,MATCH($B10,팀별분석!$Q$9:$Q$48,0)),"명단확인")) -> 사업운영팀 기획1파트 | B10: 홍길동 | C10: 채널 개편 PJT | D10: =IF($C10="","",IFERROR(INDEX(사업정보!$B$6:$B$35,MATCH($C10,사업정보!$A$6:$A$35,0)),"사업명확인")) -> 사업 | E10: 0.3 | F10: 0.3 | G10: 0.3 | H10: 0.3 | I10: 0.3 | J10: 0.3 | Q10: =IF($B10="",0,SUM(E10:P10)) -> 1.8 | R10: =IF($B10="",0,IFERROR(Q10*INDEX(사업정보!$F$6:$F$35,MATCH($C10,사업정보!$A$6:$A$35,0))/INDEX(사업정보!$I$6:$I$35,MATCH($C10,사업정보!$A$6:$A$35,0)),0)) -> 58125000 | S10: =IF($B10="",0,IFERROR(Q10*INDEX(사업정보!$G$6:$G$35,MATCH($C10,사업정보!$A$6:$A$35,0))/INDEX(사업정보!$I$6:$I$35,MATCH($C10,사업정보!$A$6:$A$35,0)),0)) -> 18000000
A11: =IF($B11="","",IFERROR(INDEX(팀별분석!$R$9:$R$48,MATCH($B11,팀별분석!$Q$9:$Q$48,0)),"명단확인")) -> 사업운영팀 기획1파트 | B11: 김영수 | C11: 차세대 ERP 구축 | D11: =IF($C11="","",IFERROR(INDEX(사업정보!$B$6:$B$35,MATCH($C11,사업정보!$A$6:$A$35,0)),"사업명확인")) -> 사업 | E11: 0.8 | F11: 0.8 | G11: 0.8 | H11: 0.8 | I11: 0.8 | J11: 0.4 | Q11: =IF($B11="",0,SUM(E11:P11)) -> 4.4 | R11: =IF($B11="",0,IFERROR(Q11*INDEX(사업정보!$F$6:$F$35,MATCH($C11,사업정보!$A$6:$A$35,0))/INDEX(사업정보!$I$6:$I$35,MATCH($C11,사업정보!$A$6:$A$35,0)),0)) -> 1.7941748e+08 | S11: =IF($B11="",0,IFERROR(Q11*INDEX(사업정보!$G$6:$G$35,MATCH($C11,사업정보!$A$6:$A$35,0))/INDEX(사업정보!$I$6:$I$35,MATCH($C11,사업정보!$A$6:$A$35,0)),0)) -> 53825243
A12: =IF($B12="","",IFERROR(INDEX(팀별분석!$R$9:$R$48,MATCH($B12,팀별분석!$Q$9:$Q$48,0)),"명단확인")) -> 사업운영팀 기획1파트 | B12: 김영수 | C12: 하반기 고도화 PJT | D12: =IF($C12="","",IFERROR(INDEX(사업정보!$B$6:$B$35,MATCH($C12,사업정보!$A$6:$A$35,0)),"사업명확인")) -> 사업 | K12: 0.9 | L12: 0.9 | M12: 0.9 | N12: 0.9 | O12: 0.9 | P12: 0.9 | Q12: =IF($B12="",0,SUM(E12:P12)) -> 5.4 | R12: =IF($B12="",0,IFERROR(Q12*INDEX(사업정보!$F$6:$F$35,MATCH($C12,사업정보!$A$6:$A$35,0))/INDEX(사업정보!$I$6:$I$35,MATCH($C12,사업정보!$A$6:$A$35,0)),0)) -> 1.6714286e+08 | S12: =IF($B12="",0,IFERROR(Q12*INDEX(사업정보!$G$6:$G$35,MATCH($C12,사업정보!$A$6:$A$35,0))/INDEX(사업정보!$I$6:$I$35,MATCH($C12,사업정보!$A$6:$A$35,0)),0)) -> 45000000
A13: =IF($B13="","",IFERROR(INDEX(팀별분석!$R$9:$R$48,MATCH($B13,팀별분석!$Q$9:$Q$48,0)),"명단확인")) -> 사업운영팀 기획1파트 | B13: 김영수 | C13: 신규 제안 지원 | D13: =IF($C13="","",IFERROR(INDEX(사업정보!$B$6:$B$35,MATCH($C13,사업정보!$A$6:$A$35,0)),"사업명확인")) -> 지원 | E13: 0.3 | F13: 0.3 | G13: 0.3 | H13: 0.3 | I13: 0.3 | J13: 0.3 | K13: 0.2 | L13: 0.2 | M13: 0.2 | N13: 0.2 | O13: 0.2 | P13: 0.2 | Q13: =IF($B13="",0,SUM(E13:P13)) -> 3 | R13: =IF($B13="",0,IFERROR(Q13*INDEX(사업정보!$F$6:$F$35,MATCH($C13,사업정보!$A$6:$A$35,0))/INDEX(사업정보!$I$6:$I$35,MATCH($C13,사업정보!$A$6:$A$35,0)),0)) -> 0 | S13: =IF($B13="",0,IFERROR(Q13*INDEX(사업정보!$G$6:$G$35,MATCH($C13,사업정보!$A$6:$A$35,0))/INDEX(사업정보!$I$6:$I$35,MATCH($C13,사업정보!$A$6:$A$35,0)),0)) -> 0
A14: =IF($B14="","",IFERROR(INDEX(팀별분석!$R$9:$R$48,MATCH($B14,팀별분석!$Q$9:$Q$48,0)),"명단확인")) -> 사업운영팀 기획1파트 | B14: 박지은 | C14: 채널 개편 PJT | D14: =IF($C14="","",IFERROR(INDEX(사업정보!$B$6:$B$35,MATCH($C14,사업정보!$A$6:$A$35,0)),"사업명확인")) -> 사업 | E14: 0.6 | F14: 0.6 | G14: 0.8 | H14: 0.8 | I14: 0.8 | J14: 0.8 | K14: 0.4 | Q14: =IF($B14="",0,SUM(E14:P14)) -> 4.8 | R14: =IF($B14="",0,IFERROR(Q14*INDEX(사업정보!$F$6:$F$35,MATCH($C14,사업정보!$A$6:$A$35,0))/INDEX(사업정보!$I$6:$I$35,MATCH($C14,사업정보!$A$6:$A$35,0)),0)) -> 155000000 | S14: =IF($B14="",0,IFERROR(Q14*INDEX(사업정보!$G$6:$G$35,MATCH($C14,사업정보!$A$6:$A$35,0))/INDEX(사업정보!$I$6:$I$35,MATCH($C14,사업정보!$A$6:$A$35,0)),0)) -> 48000000
A15: =IF($B15="","",IFERROR(INDEX(팀별분석!$R$9:$R$48,MATCH($B15,팀별분석!$Q$9:$Q$48,0)),"명단확인")) -> 사업운영팀 기획1파트 | B15: 박지은 | C15: 운영 이관 지원 | D15: =IF($C15="","",IFERROR(INDEX(사업정보!$B$6:$B$35,MATCH($C15,사업정보!$A$6:$A$35,0)),"사업명확인")) -> 지원 | L15: 0.6 | M15: 0.6 | N15: 0.6 | O15: 0.6 | P15: 0.6 | Q15: =IF($B15="",0,SUM(E15:P15)) -> 3 | R15: =IF($B15="",0,IFERROR(Q15*INDEX(사업정보!$F$6:$F$35,MATCH($C15,사업정보!$A$6:$A$35,0))/INDEX(사업정보!$I$6:$I$35,MATCH($C15,사업정보!$A$6:$A$35,0)),0)) -> 0 | S15: =IF($B15="",0,IFERROR(Q15*INDEX(사업정보!$G$6:$G$35,MATCH($C15,사업정보!$A$6:$A$35,0))/INDEX(사업정보!$I$6:$I$35,MATCH($C15,사업정보!$A$6:$A$35,0)),0)) -> 0
A16: =IF($B16="","",IFERROR(INDEX(팀별분석!$R$9:$R$48,MATCH($B16,팀별분석!$Q$9:$Q$48,0)),"명단확인")) -> 사업운영팀 기획1파트 | B16: 박지은 | C16: 파트 상시 운영업무 | D16: =IF($C16="","",IFERROR(INDEX(사업정보!$B$6:$B$35,MATCH($C16,사업정보!$A$6:$A$35,0)),"사업명확인")) -> 운영 | E16: 0.3 | F16: 0.3 | G16: 0.3 | H16: 0.3 | I16: 0.3 | J16: 0.3 | K16: 0.3 | L16: 0.3 | M16: 0.3 | N16: 0.3 | O16: 0.3 | P16: 0.3 | Q16: =IF($B16="",0,SUM(E16:P16)) -> 3.6 | R16: =IF($B16="",0,IFERROR(Q16*INDEX(사업정보!$F$6:$F$35,MATCH($C16,사업정보!$A$6:$A$35,0))/INDEX(사업정보!$I$6:$I$35,MATCH($C16,사업정보!$A$6:$A$35,0)),0)) -> 0 | S16: =IF($B16="",0,IFERROR(Q16*INDEX(사업정보!$G$6:$G$35,MATCH($C16,사업정보!$A$6:$A$35,0))/INDEX(사업정보!$I$6:$I$35,MATCH($C16,사업정보!$A$6:$A$35,0)),0)) -> 0
A17: =IF($B17="","",IFERROR(INDEX(팀별분석!$R$9:$R$48,MATCH($B17,팀별분석!$Q$9:$Q$48,0)),"명단확인")) -> 사업운영팀 기획1파트 | B17: 최민호 | C17: 파트 상시 운영업무 | D17: =IF($C17="","",IFERROR(INDEX(사업정보!$B$6:$B$35,MATCH($C17,사업정보!$A$6:$A$35,0)),"사업명확인")) -> 운영 | E17: 0.4 | F17: 0.4 | G17: 0.4 | H17: 0.4 | I17: 0.4 | J17: 0.4 | K17: 0.4 | L17: 0.4 | M17: 0.4 | N17: 0.4 | O17: 0.4 | P17: 0.4 | Q17: =IF($B17="",0,SUM(E17:P17)) -> 4.8 | R17: =IF($B17="",0,IFERROR(Q17*INDEX(사업정보!$F$6:$F$35,MATCH($C17,사업정보!$A$6:$A$35,0))/INDEX(사업정보!$I$6:$I$35,MATCH($C17,사업정보!$A$6:$A$35,0)),0)) -> 0 | S17: =IF($B17="",0,IFERROR(Q17*INDEX(사업정보!$G$6:$G$35,MATCH($C17,사업정보!$A$6:$A$35,0))/INDEX(사업정보!$I$6:$I$35,MATCH($C17,사업정보!$A$6:$A$35,0)),0)) -> 0
A18: =IF($B18="","",IFERROR(INDEX(팀별분석!$R$9:$R$48,MATCH($B18,팀별분석!$Q$9:$Q$48,0)),"명단확인")) -> 사업운영팀 기획1파트 | B18: 최민호 | C18: 채널 개편 PJT | D18: =IF($C18="","",IFERROR(INDEX(사업정보!$B$6:$B$35,MATCH($C18,사업정보!$A$6:$A$35,0)),"사업명확인")) -> 사업 | E18: 0.5 | F18: 0.5 | G18: 0.5 | H18: 0.5 | I18: 0.5 | J18: 0.5 | Q18: =IF($B18="",0,SUM(E18:P18)) -> 3 | R18: =IF($B18="",0,IFERROR(Q18*INDEX(사업정보!$F$6:$F$35,MATCH($C18,사업정보!$A$6:$A$35,0))/INDEX(사업정보!$I$6:$I$35,MATCH($C18,사업정보!$A$6:$A$35,0)),0)) -> 96875000 | S18: =IF($B18="",0,IFERROR(Q18*INDEX(사업정보!$G$6:$G$35,MATCH($C18,사업정보!$A$6:$A$35,0))/INDEX(사업정보!$I$6:$I$35,MATCH($C18,사업정보!$A$6:$A$35,0)),0)) -> 30000000
A19: =IF($B19="","",IFERROR(INDEX(팀별분석!$R$9:$R$48,MATCH($B19,팀별분석!$Q$9:$Q$48,0)),"명단확인")) -> 사업운영팀 기획1파트 | B19: 최민호 | C19: 신규 제안 지원 | D19: =IF($C19="","",IFERROR(INDEX(사업정보!$B$6:$B$35,MATCH($C19,사업정보!$A$6:$A$35,0)),"사업명확인")) -> 지원 | K19: 0.3 | L19: 0.3 | M19: 0.3 | N19: 0.3 | O19: 0.3 | P19: 0.3 | Q19: =IF($B19="",0,SUM(E19:P19)) -> 1.8 | R19: =IF($B19="",0,IFERROR(Q19*INDEX(사업정보!$F$6:$F$35,MATCH($C19,사업정보!$A$6:$A$35,0))/INDEX(사업정보!$I$6:$I$35,MATCH($C19,사업정보!$A$6:$A$35,0)),0)) -> 0 | S19: =IF($B19="",0,IFERROR(Q19*INDEX(사업정보!$G$6:$G$35,MATCH($C19,사업정보!$A$6:$A$35,0))/INDEX(사업정보!$I$6:$I$35,MATCH($C19,사업정보!$A$6:$A$35,0)),0)) -> 0
A20: =IF($B20="","",IFERROR(INDEX(팀별분석!$R$9:$R$48,MATCH($B20,팀별분석!$Q$9:$Q$48,0)),"명단확인")) -> 사업운영팀 기획1파트 | B20: 정수아 | C20: 정산·계약 운영 | D20: =IF($C20="","",IFERROR(INDEX(사업정보!$B$6:$B$35,MATCH($C20,사업정보!$A$6:$A$35,0)),"사업명확인")) -> 운영 | E20: 0.5 | F20: 0.5 | G20: 0.5 | H20: 0.5 | I20: 0.5 | J20: 0.5 | K20: 0.5 | L20: 0.5 | M20: 0.5 | N20: 0.5 | O20: 0.5 | P20: 0.5 | Q20: =IF($B20="",0,SUM(E20:P20)) -> 6 | R20: =IF($B20="",0,IFERROR(Q20*INDEX(사업정보!$F$6:$F$35,MATCH($C20,사업정보!$A$6:$A$35,0))/INDEX(사업정보!$I$6:$I$35,MATCH($C20,사업정보!$A$6:$A$35,0)),0)) -> 0 | S20: =IF($B20="",0,IFERROR(Q20*INDEX(사업정보!$G$6:$G$35,MATCH($C20,사업정보!$A$6:$A$35,0))/INDEX(사업정보!$I$6:$I$35,MATCH($C20,사업정보!$A$6:$A$35,0)),0)) -> 0
A21: =IF($B21="","",IFERROR(INDEX(팀별분석!$R$9:$R$48,MATCH($B21,팀별분석!$Q$9:$Q$48,0)),"명단확인")) -> 사업운영팀 기획1파트 | B21: 정수아 | C21: 차세대 ERP 구축 | D21: =IF($C21="","",IFERROR(INDEX(사업정보!$B$6:$B$35,MATCH($C21,사업정보!$A$6:$A$35,0)),"사업명확인")) -> 사업 | E21: 0.4 | F21: 0.6 | G21: 0.6 | H21: 0.6 | I21: 0.6 | Q21: =IF($B21="",0,SUM(E21:P21)) -> 2.8 | R21: =IF($B21="",0,IFERROR(Q21*INDEX(사업정보!$F$6:$F$35,MATCH($C21,사업정보!$A$6:$A$35,0))/INDEX(사업정보!$I$6:$I$35,MATCH($C21,사업정보!$A$6:$A$35,0)),0)) -> 1.1417476e+08 | S21: =IF($B21="",0,IFERROR(Q21*INDEX(사업정보!$G$6:$G$35,MATCH($C21,사업정보!$A$6:$A$35,0))/INDEX(사업정보!$I$6:$I$35,MATCH($C21,사업정보!$A$6:$A$35,0)),0)) -> 34252427
A22: =IF($B22="","",IFERROR(INDEX(팀별분석!$R$9:$R$48,MATCH($B22,팀별분석!$Q$9:$Q$48,0)),"명단확인")) -> 사업운영팀 기획1파트 | B22: 정수아 | C22: 하반기 고도화 PJT | D22: =IF($C22="","",IFERROR(INDEX(사업정보!$B$6:$B$35,MATCH($C22,사업정보!$A$6:$A$35,0)),"사업명확인")) -> 사업 | K22: 0.5 | L22: 0.5 | M22: 0.5 | N22: 0.5 | O22: 0.5 | P22: 0.5 | Q22: =IF($B22="",0,SUM(E22:P22)) -> 3 | R22: =IF($B22="",0,IFERROR(Q22*INDEX(사업정보!$F$6:$F$35,MATCH($C22,사업정보!$A$6:$A$35,0))/INDEX(사업정보!$I$6:$I$35,MATCH($C22,사업정보!$A$6:$A$35,0)),0)) -> 92857143 | S22: =IF($B22="",0,IFERROR(Q22*INDEX(사업정보!$G$6:$G$35,MATCH($C22,사업정보!$A$6:$A$35,0))/INDEX(사업정보!$I$6:$I$35,MATCH($C22,사업정보!$A$6:$A$35,0)),0)) -> 25000000
A23: =IF($B23="","",IFERROR(INDEX(팀별분석!$R$9:$R$48,MATCH($B23,팀별분석!$Q$9:$Q$48,0)),"명단확인")) -> 사업운영팀 기획2파트 | B23: 김철수 | C23: 물류 시스템 고도화 | D23: =IF($C23="","",IFERROR(INDEX(사업정보!$B$6:$B$35,MATCH($C23,사업정보!$A$6:$A$35,0)),"사업명확인")) -> 사업 | G23: 0.9 | H23: 0.9 | I23: 0.9 | J23: 0.9 | K23: 0.9 | Q23: =IF($B23="",0,SUM(E23:P23)) -> 4.5 | R23: =IF($B23="",0,IFERROR(Q23*INDEX(사업정보!$F$6:$F$35,MATCH($C23,사업정보!$A$6:$A$35,0))/INDEX(사업정보!$I$6:$I$35,MATCH($C23,사업정보!$A$6:$A$35,0)),0)) -> 126000000 | S23: =IF($B23="",0,IFERROR(Q23*INDEX(사업정보!$G$6:$G$35,MATCH($C23,사업정보!$A$6:$A$35,0))/INDEX(사업정보!$I$6:$I$35,MATCH($C23,사업정보!$A$6:$A$35,0)),0)) -> 35100000
A24: =IF($B24="","",IFERROR(INDEX(팀별분석!$R$9:$R$48,MATCH($B24,팀별분석!$Q$9:$Q$48,0)),"명단확인")) -> 사업운영팀 기획2파트 | B24: 김철수 | C24: 유지보수 대응 | D24: =IF($C24="","",IFERROR(INDEX(사업정보!$B$6:$B$35,MATCH($C24,사업정보!$A$6:$A$35,0)),"사업명확인")) -> 운영 | E24: 0.4 | F24: 0.4 | L24: 0.5 | M24: 0.5 | N24: 0.5 | O24: 0.5 | P24: 0.5 | Q24: =IF($B24="",0,SUM(E24:P24)) -> 3.3 | R24: =IF($B24="",0,IFERROR(Q24*INDEX(사업정보!$F$6:$F$35,MATCH($C24,사업정보!$A$6:$A$35,0))/INDEX(사업정보!$I$6:$I$35,MATCH($C24,사업정보!$A$6:$A$35,0)),0)) -> 0 | S24: =IF($B24="",0,IFERROR(Q24*INDEX(사업정보!$G$6:$G$35,MATCH($C24,사업정보!$A$6:$A$35,0))/INDEX(사업정보!$I$6:$I$35,MATCH($C24,사업정보!$A$6:$A$35,0)),0)) -> 0
A25: =IF($B25="","",IFERROR(INDEX(팀별분석!$R$9:$R$48,MATCH($B25,팀별분석!$Q$9:$Q$48,0)),"명단확인")) -> 사업운영팀 기획2파트 | B25: 이하늘 | C25: 물류 시스템 고도화 | D25: =IF($C25="","",IFERROR(INDEX(사업정보!$B$6:$B$35,MATCH($C25,사업정보!$A$6:$A$35,0)),"사업명확인")) -> 사업 | G25: 0.8 | H25: 0.8 | I25: 0.8 | J25: 0.8 | K25: 0.8 | Q25: =IF($B25="",0,SUM(E25:P25)) -> 4 | R25: =IF($B25="",0,IFERROR(Q25*INDEX(사업정보!$F$6:$F$35,MATCH($C25,사업정보!$A$6:$A$35,0))/INDEX(사업정보!$I$6:$I$35,MATCH($C25,사업정보!$A$6:$A$35,0)),0)) -> 112000000 | S25: =IF($B25="",0,IFERROR(Q25*INDEX(사업정보!$G$6:$G$35,MATCH($C25,사업정보!$A$6:$A$35,0))/INDEX(사업정보!$I$6:$I$35,MATCH($C25,사업정보!$A$6:$A$35,0)),0)) -> 31200000
A26: =IF($B26="","",IFERROR(INDEX(팀별분석!$R$9:$R$48,MATCH($B26,팀별분석!$Q$9:$Q$48,0)),"명단확인")) -> 사업운영팀 기획2파트 | B26: 이하늘 | C26: 데이터 표준화 PJT | D26: =IF($C26="","",IFERROR(INDEX(사업정보!$B$6:$B$35,MATCH($C26,사업정보!$A$6:$A$35,0)),"사업명확인")) -> 사업 | E26: 0.3 | F26: 0.3 | G26: 0.3 | H26: 0.3 | I26: 0.3 | J26: 0.3 | Q26: =IF($B26="",0,SUM(E26:P26)) -> 1.8 | R26: =IF($B26="",0,IFERROR(Q26*INDEX(사업정보!$F$6:$F$35,MATCH($C26,사업정보!$A$6:$A$35,0))/INDEX(사업정보!$I$6:$I$35,MATCH($C26,사업정보!$A$6:$A$35,0)),0)) -> 28125000 | S26: =IF($B26="",0,IFERROR(Q26*INDEX(사업정보!$G$6:$G$35,MATCH($C26,사업정보!$A$6:$A$35,0))/INDEX(사업정보!$I$6:$I$35,MATCH($C26,사업정보!$A$6:$A$35,0)),0)) -> 7125000
A27: =IF($B27="","",IFERROR(INDEX(팀별분석!$R$9:$R$48,MATCH($B27,팀별분석!$Q$9:$Q$48,0)),"명단확인")) -> 사업운영팀 기획2파트 | B27: 오세훈 | C27: 파트 상시 운영업무 | D27: =IF($C27="","",IFERROR(INDEX(사업정보!$B$6:$B$35,MATCH($C27,사업정보!$A$6:$A$35,0)),"사업명확인")) -> 운영 | E27: 0.3 | F27: 0.3 | G27: 0.3 | H27: 0.3 | I27: 0.3 | J27: 0.3 | K27: 0.3 | L27: 0.3 | M27: 0.3 | N27: 0.3 | O27: 0.3 | P27: 0.3 | Q27: =IF($B27="",0,SUM(E27:P27)) -> 3.6 | R27: =IF($B27="",0,IFERROR(Q27*INDEX(사업정보!$F$6:$F$35,MATCH($C27,사업정보!$A$6:$A$35,0))/INDEX(사업정보!$I$6:$I$35,MATCH($C27,사업정보!$A$6:$A$35,0)),0)) -> 0 | S27: =IF($B27="",0,IFERROR(Q27*INDEX(사업정보!$G$6:$G$35,MATCH($C27,사업정보!$A$6:$A$35,0))/INDEX(사업정보!$I$6:$I$35,MATCH($C27,사업정보!$A$6:$A$35,0)),0)) -> 0
A28: =IF($B28="","",IFERROR(INDEX(팀별분석!$R$9:$R$48,MATCH($B28,팀별분석!$Q$9:$Q$48,0)),"명단확인")) -> 사업운영팀 기획2파트 | B28: 오세훈 | C28: 데이터 표준화 PJT | D28: =IF($C28="","",IFERROR(INDEX(사업정보!$B$6:$B$35,MATCH($C28,사업정보!$A$6:$A$35,0)),"사업명확인")) -> 사업 | E28: 0.6 | F28: 0.6 | G28: 0.6 | H28: 0.6 | I28: 0.6 | J28: 0.6 | Q28: =IF($B28="",0,SUM(E28:P28)) -> 3.6 | R28: =IF($B28="",0,IFERROR(Q28*INDEX(사업정보!$F$6:$F$35,MATCH($C28,사업정보!$A$6:$A$35,0))/INDEX(사업정보!$I$6:$I$35,MATCH($C28,사업정보!$A$6:$A$35,0)),0)) -> 56250000 | S28: =IF($B28="",0,IFERROR(Q28*INDEX(사업정보!$G$6:$G$35,MATCH($C28,사업정보!$A$6:$A$35,0))/INDEX(사업정보!$I$6:$I$35,MATCH($C28,사업정보!$A$6:$A$35,0)),0)) -> 14250000
A29: =IF($B29="","",IFERROR(INDEX(팀별분석!$R$9:$R$48,MATCH($B29,팀별분석!$Q$9:$Q$48,0)),"명단확인")) -> 사업운영팀 기획2파트 | B29: 서정민 | C29: 데이터 표준화 PJT | D29: =IF($C29="","",IFERROR(INDEX(사업정보!$B$6:$B$35,MATCH($C29,사업정보!$A$6:$A$35,0)),"사업명확인")) -> 사업 | E29: 0.7 | F29: 0.7 | G29: 0.7 | H29: 0.7 | I29: 0.7 | J29: 0.7 | Q29: =IF($B29="",0,SUM(E29:P29)) -> 4.2 | R29: =IF($B29="",0,IFERROR(Q29*INDEX(사업정보!$F$6:$F$35,MATCH($C29,사업정보!$A$6:$A$35,0))/INDEX(사업정보!$I$6:$I$35,MATCH($C29,사업정보!$A$6:$A$35,0)),0)) -> 65625000 | S29: =IF($B29="",0,IFERROR(Q29*INDEX(사업정보!$G$6:$G$35,MATCH($C29,사업정보!$A$6:$A$35,0))/INDEX(사업정보!$I$6:$I$35,MATCH($C29,사업정보!$A$6:$A$35,0)),0)) -> 16625000
A30: =IF($B30="","",IFERROR(INDEX(팀별분석!$R$9:$R$48,MATCH($B30,팀별분석!$Q$9:$Q$48,0)),"명단확인")) -> 사업운영팀 기획2파트 | B30: 서정민 | C30: 물류 시스템 고도화 | D30: =IF($C30="","",IFERROR(INDEX(사업정보!$B$6:$B$35,MATCH($C30,사업정보!$A$6:$A$35,0)),"사업명확인")) -> 사업 | G30: 0.3 | H30: 0.3 | I30: 0.3 | J30: 0.3 | K30: 0.3 | Q30: =IF($B30="",0,SUM(E30:P30)) -> 1.5 | R30: =IF($B30="",0,IFERROR(Q30*INDEX(사업정보!$F$6:$F$35,MATCH($C30,사업정보!$A$6:$A$35,0))/INDEX(사업정보!$I$6:$I$35,MATCH($C30,사업정보!$A$6:$A$35,0)),0)) -> 42000000 | S30: =IF($B30="",0,IFERROR(Q30*INDEX(사업정보!$G$6:$G$35,MATCH($C30,사업정보!$A$6:$A$35,0))/INDEX(사업정보!$I$6:$I$35,MATCH($C30,사업정보!$A$6:$A$35,0)),0)) -> 11700000
A31: =IF($B31="","",IFERROR(INDEX(팀별분석!$R$9:$R$48,MATCH($B31,팀별분석!$Q$9:$Q$48,0)),"명단확인")) -> 신사업팀 | B31: 이영희 | C31: 신규 사업 타당성 검토 | D31: =IF($C31="","",IFERROR(INDEX(사업정보!$B$6:$B$35,MATCH($C31,사업정보!$A$6:$A$35,0)),"사업명확인")) -> 사업 | E31: 0.6 | F31: 0.6 | G31: 0.6 | H31: 0.6 | Q31: =IF($B31="",0,SUM(E31:P31)) -> 2.4 | R31: =IF($B31="",0,IFERROR(Q31*INDEX(사업정보!$F$6:$F$35,MATCH($C31,사업정보!$A$6:$A$35,0))/INDEX(사업정보!$I$6:$I$35,MATCH($C31,사업정보!$A$6:$A$35,0)),0)) -> 32727273 | S31: =IF($B31="",0,IFERROR(Q31*INDEX(사업정보!$G$6:$G$35,MATCH($C31,사업정보!$A$6:$A$35,0))/INDEX(사업정보!$I$6:$I$35,MATCH($C31,사업정보!$A$6:$A$35,0)),0)) -> 6545454.5
A32: =IF($B32="","",IFERROR(INDEX(팀별분석!$R$9:$R$48,MATCH($B32,팀별분석!$Q$9:$Q$48,0)),"명단확인")) -> 신사업팀 | B32: 이영희 | C32: 파트너십 발굴 | D32: =IF($C32="","",IFERROR(INDEX(사업정보!$B$6:$B$35,MATCH($C32,사업정보!$A$6:$A$35,0)),"사업명확인")) -> 사업 | I32: 0.5 | J32: 0.5 | K32: 0.5 | L32: 0.5 | M32: 0.5 | N32: 0.5 | O32: 0.5 | P32: 0.5 | Q32: =IF($B32="",0,SUM(E32:P32)) -> 4 | R32: =IF($B32="",0,IFERROR(Q32*INDEX(사업정보!$F$6:$F$35,MATCH($C32,사업정보!$A$6:$A$35,0))/INDEX(사업정보!$I$6:$I$35,MATCH($C32,사업정보!$A$6:$A$35,0)),0)) -> 24324324 | S32: =IF($B32="",0,IFERROR(Q32*INDEX(사업정보!$G$6:$G$35,MATCH($C32,사업정보!$A$6:$A$35,0))/INDEX(사업정보!$I$6:$I$35,MATCH($C32,사업정보!$A$6:$A$35,0)),0)) -> 4864864.9
A33: =IF($B33="","",IFERROR(INDEX(팀별분석!$R$9:$R$48,MATCH($B33,팀별분석!$Q$9:$Q$48,0)),"명단확인")) -> 신사업팀 | B33: 한지훈 | C33: 시장조사 | D33: =IF($C33="","",IFERROR(INDEX(사업정보!$B$6:$B$35,MATCH($C33,사업정보!$A$6:$A$35,0)),"사업명확인")) -> 지원 | E33: 0.4 | F33: 0.4 | G33: 0.4 | H33: 0.4 | I33: 0.4 | J33: 0.4 | Q33: =IF($B33="",0,SUM(E33:P33)) -> 2.4 | R33: =IF($B33="",0,IFERROR(Q33*INDEX(사업정보!$F$6:$F$35,MATCH($C33,사업정보!$A$6:$A$35,0))/INDEX(사업정보!$I$6:$I$35,MATCH($C33,사업정보!$A$6:$A$35,0)),0)) -> 0 | S33: =IF($B33="",0,IFERROR(Q33*INDEX(사업정보!$G$6:$G$35,MATCH($C33,사업정보!$A$6:$A$35,0))/INDEX(사업정보!$I$6:$I$35,MATCH($C33,사업정보!$A$6:$A$35,0)),0)) -> 0
A34: =IF($B34="","",IFERROR(INDEX(팀별분석!$R$9:$R$48,MATCH($B34,팀별분석!$Q$9:$Q$48,0)),"명단확인")) -> 신사업팀 | B34: 한지훈 | C34: 신규 사업 타당성 검토 | D34: =IF($C34="","",IFERROR(INDEX(사업정보!$B$6:$B$35,MATCH($C34,사업정보!$A$6:$A$35,0)),"사업명확인")) -> 사업 | E34: 0.5 | F34: 0.5 | G34: 0.5 | H34: 0.5 | Q34: =IF($B34="",0,SUM(E34:P34)) -> 2 | R34: =IF($B34="",0,IFERROR(Q34*INDEX(사업정보!$F$6:$F$35,MATCH($C34,사업정보!$A$6:$A$35,0))/INDEX(사업정보!$I$6:$I$35,MATCH($C34,사업정보!$A$6:$A$35,0)),0)) -> 27272727 | S34: =IF($B34="",0,IFERROR(Q34*INDEX(사업정보!$G$6:$G$35,MATCH($C34,사업정보!$A$6:$A$35,0))/INDEX(사업정보!$I$6:$I$35,MATCH($C34,사업정보!$A$6:$A$35,0)),0)) -> 5454545.5
A35: =IF($B35="","",IFERROR(INDEX(팀별분석!$R$9:$R$48,MATCH($B35,팀별분석!$Q$9:$Q$48,0)),"명단확인")) -> 신사업팀 | B35: 문가영 | C35: 파트너십 발굴 | D35: =IF($C35="","",IFERROR(INDEX(사업정보!$B$6:$B$35,MATCH($C35,사업정보!$A$6:$A$35,0)),"사업명확인")) -> 사업 | E35: 0.6 | F35: 0.6 | G35: 0.6 | H35: 0.6 | I35: 0.6 | J35: 0.6 | K35: 0.6 | L35: 0.6 | M35: 0.6 | N35: 0.6 | O35: 0.6 | P35: 0.6 | Q35: =IF($B35="",0,SUM(E35:P35)) -> 7.2 | R35: =IF($B35="",0,IFERROR(Q35*INDEX(사업정보!$F$6:$F$35,MATCH($C35,사업정보!$A$6:$A$35,0))/INDEX(사업정보!$I$6:$I$35,MATCH($C35,사업정보!$A$6:$A$35,0)),0)) -> 43783784 | S35: =IF($B35="",0,IFERROR(Q35*INDEX(사업정보!$G$6:$G$35,MATCH($C35,사업정보!$A$6:$A$35,0))/INDEX(사업정보!$I$6:$I$35,MATCH($C35,사업정보!$A$6:$A$35,0)),0)) -> 8756756.8
A36: =IF($B36="","",IFERROR(INDEX(팀별분석!$R$9:$R$48,MATCH($B36,팀별분석!$Q$9:$Q$48,0)),"명단확인")) -> 경영본부 사업기획실 | B36: 박민수 | C36: 전사 예산 수립 지원 | D36: =IF($C36="","",IFERROR(INDEX(사업정보!$B$6:$B$35,MATCH($C36,사업정보!$A$6:$A$35,0)),"사업명확인")) -> 지원 | E36: 0.5 | F36: 0.5 | G36: 0.3 | H36: 0.3 | I36: 0.3 | J36: 0.3 | K36: 0.5 | L36: 0.5 | M36: 0.5 | N36: 0.7 | O36: 0.8 | P36: 0.8 | Q36: =IF($B36="",0,SUM(E36:P36)) -> 6 | R36: =IF($B36="",0,IFERROR(Q36*INDEX(사업정보!$F$6:$F$35,MATCH($C36,사업정보!$A$6:$A$35,0))/INDEX(사업정보!$I$6:$I$35,MATCH($C36,사업정보!$A$6:$A$35,0)),0)) -> 0 | S36: =IF($B36="",0,IFERROR(Q36*INDEX(사업정보!$G$6:$G$35,MATCH($C36,사업정보!$A$6:$A$35,0))/INDEX(사업정보!$I$6:$I$35,MATCH($C36,사업정보!$A$6:$A$35,0)),0)) -> 0
A37: =IF($B37="","",IFERROR(INDEX(팀별분석!$R$9:$R$48,MATCH($B37,팀별분석!$Q$9:$Q$48,0)),"명단확인")) -> 경영본부 사업기획실 | B37: 박민수 | C37: 중장기 전략 수립 | D37: =IF($C37="","",IFERROR(INDEX(사업정보!$B$6:$B$35,MATCH($C37,사업정보!$A$6:$A$35,0)),"사업명확인")) -> 사업 | E37: 0.3 | F37: 0.3 | G37: 0.3 | H37: 0.3 | I37: 0.3 | J37: 0.3 | K37: 0.3 | L37: 0.3 | M37: 0.3 | N37: 0.3 | O37: 0.3 | P37: 0.3 | Q37: =IF($B37="",0,SUM(E37:P37)) -> 3.6 | R37: =IF($B37="",0,IFERROR(Q37*INDEX(사업정보!$F$6:$F$35,MATCH($C37,사업정보!$A$6:$A$35,0))/INDEX(사업정보!$I$6:$I$35,MATCH($C37,사업정보!$A$6:$A$35,0)),0)) -> 23333333 | S37: =IF($B37="",0,IFERROR(Q37*INDEX(사업정보!$G$6:$G$35,MATCH($C37,사업정보!$A$6:$A$35,0))/INDEX(사업정보!$I$6:$I$35,MATCH($C37,사업정보!$A$6:$A$35,0)),0)) -> 3333333.3
A38: =IF($B38="","",IFERROR(INDEX(팀별분석!$R$9:$R$48,MATCH($B38,팀별분석!$Q$9:$Q$48,0)),"명단확인")) -> 경영본부 사업기획실 | B38: 윤소라 | C38: 경영실적 분석 운영 | D38: =IF($C38="","",IFERROR(INDEX(사업정보!$B$6:$B$35,MATCH($C38,사업정보!$A$6:$A$35,0)),"사업명확인")) -> 운영 | E38: 0.5 | F38: 0.5 | G38: 0.5 | H38: 0.5 | I38: 0.5 | J38: 0.5 | K38: 0.5 | L38: 0.5 | M38: 0.5 | N38: 0.5 | O38: 0.5 | P38: 0.5 | Q38: =IF($B38="",0,SUM(E38:P38)) -> 6 | R38: =IF($B38="",0,IFERROR(Q38*INDEX(사업정보!$F$6:$F$35,MATCH($C38,사업정보!$A$6:$A$35,0))/INDEX(사업정보!$I$6:$I$35,MATCH($C38,사업정보!$A$6:$A$35,0)),0)) -> 0 | S38: =IF($B38="",0,IFERROR(Q38*INDEX(사업정보!$G$6:$G$35,MATCH($C38,사업정보!$A$6:$A$35,0))/INDEX(사업정보!$I$6:$I$35,MATCH($C38,사업정보!$A$6:$A$35,0)),0)) -> 0
A39: =IF($B39="","",IFERROR(INDEX(팀별분석!$R$9:$R$48,MATCH($B39,팀별분석!$Q$9:$Q$48,0)),"명단확인")) -> 경영본부 사업기획실 | B39: 윤소라 | C39: 파트너십 발굴 | D39: =IF($C39="","",IFERROR(INDEX(사업정보!$B$6:$B$35,MATCH($C39,사업정보!$A$6:$A$35,0)),"사업명확인")) -> 사업 | E39: 0.3 | F39: 0.3 | G39: 0.3 | H39: 0.3 | I39: 0.3 | J39: 0.3 | K39: 0.3 | L39: 0.3 | M39: 0.3 | N39: 0.3 | O39: 0.3 | P39: 0.3 | Q39: =IF($B39="",0,SUM(E39:P39)) -> 3.6 | R39: =IF($B39="",0,IFERROR(Q39*INDEX(사업정보!$F$6:$F$35,MATCH($C39,사업정보!$A$6:$A$35,0))/INDEX(사업정보!$I$6:$I$35,MATCH($C39,사업정보!$A$6:$A$35,0)),0)) -> 21891892 | S39: =IF($B39="",0,IFERROR(Q39*INDEX(사업정보!$G$6:$G$35,MATCH($C39,사업정보!$A$6:$A$35,0))/INDEX(사업정보!$I$6:$I$35,MATCH($C39,사업정보!$A$6:$A$35,0)),0)) -> 4378378.4
A40: =IF($B40="","",IFERROR(INDEX(팀별분석!$R$9:$R$48,MATCH($B40,팀별분석!$Q$9:$Q$48,0)),"명단확인")) -> 경영본부 사업기획실 | B40: 강대현 | C40: 중장기 전략 수립 | D40: =IF($C40="","",IFERROR(INDEX(사업정보!$B$6:$B$35,MATCH($C40,사업정보!$A$6:$A$35,0)),"사업명확인")) -> 사업 | E40: 0.6 | F40: 0.6 | G40: 0.6 | H40: 0.6 | I40: 0.6 | J40: 0.6 | K40: 0.6 | L40: 0.6 | M40: 0.6 | N40: 0.6 | O40: 0.6 | P40: 0.6 | Q40: =IF($B40="",0,SUM(E40:P40)) -> 7.2 | R40: =IF($B40="",0,IFERROR(Q40*INDEX(사업정보!$F$6:$F$35,MATCH($C40,사업정보!$A$6:$A$35,0))/INDEX(사업정보!$I$6:$I$35,MATCH($C40,사업정보!$A$6:$A$35,0)),0)) -> 46666667 | S40: =IF($B40="",0,IFERROR(Q40*INDEX(사업정보!$G$6:$G$35,MATCH($C40,사업정보!$A$6:$A$35,0))/INDEX(사업정보!$I$6:$I$35,MATCH($C40,사업정보!$A$6:$A$35,0)),0)) -> 6666666.7
A41: =IF($B41="","",IFERROR(INDEX(팀별분석!$R$9:$R$48,MATCH($B41,팀별분석!$Q$9:$Q$48,0)),"명단확인")) -> 경영본부 사업기획실 | B41: 강대현 | C41: 이사회 보고 지원 | D41: =IF($C41="","",IFERROR(INDEX(사업정보!$B$6:$B$35,MATCH($C41,사업정보!$A$6:$A$35,0)),"사업명확인")) -> 지원 | N41: 0.4 | O41: 0.4 | P41: 0.4 | Q41: =IF($B41="",0,SUM(E41:P41)) -> 1.2 | R41: =IF($B41="",0,IFERROR(Q41*INDEX(사업정보!$F$6:$F$35,MATCH($C41,사업정보!$A$6:$A$35,0))/INDEX(사업정보!$I$6:$I$35,MATCH($C41,사업정보!$A$6:$A$35,0)),0)) -> 0 | S41: =IF($B41="",0,IFERROR(Q41*INDEX(사업정보!$G$6:$G$35,MATCH($C41,사업정보!$A$6:$A$35,0))/INDEX(사업정보!$I$6:$I$35,MATCH($C41,사업정보!$A$6:$A$35,0)),0)) -> 0
A42: =IF($B42="","",IFERROR(INDEX(팀별분석!$R$9:$R$48,MATCH($B42,팀별분석!$Q$9:$Q$48,0)),"명단확인")) | D42: =IF($C42="","",IFERROR(INDEX(사업정보!$B$6:$B$35,MATCH($C42,사업정보!$A$6:$A$35,0)),"사업명확인")) | Q42: =IF($B42="",0,SUM(E42:P42)) -> 0 | R42: =IF($B42="",0,IFERROR(Q42*INDEX(사업정보!$F$6:$F$35,MATCH($C42,사업정보!$A$6:$A$35,0))/INDEX(사업정보!$I$6:$I$35,MATCH($C42,사업정보!$A$6:$A$35,0)),0)) -> 0 | S42: =IF($B42="",0,IFERROR(Q42*INDEX(사업정보!$G$6:$G$35,MATCH($C42,사업정보!$A$6:$A$35,0))/INDEX(사업정보!$I$6:$I$35,MATCH($C42,사업정보!$A$6:$A$35,0)),0)) -> 0
...

Sheet 팀별분석
A1: 팀별 컨디션 & 수주·이윤 분석
A2: 노란색 셀(유효가동률·기준월·인원수·목표 수주액·목표 이윤)만 입력하면 나머지는 자동 계산됩니다.
A4: 유효가동률 | B4: 0.85 | C4: 연차·교육·전사 회의를 뺀 실제 업무 가능 비율. 1명의 월 가용 M/M = 1.0 × 이 값
A5: 기준월 (경과 월수) | B5: =MONTH(TODAY()) -> 8 | C5: 올해 몇 개월이 지났는지. 수주 달성률과 비교할 기간 진도율 계산에 씁니다.
A6: 기간 진도율 | B6: =$B$5/12 -> 0.66666667 | C6: 산술적으로 이만큼은 수주했어야 정상이라는 참고선입니다. 판정이 아닌 진도 비교용. | P6: ⓪ 인력 마스터
P7: 여기 등록한 이름이 월간투입 시트 드롭다운에 나옵니다.
A8: ① 팀 구성 | P8: No | Q8: 담당자 | R8: 소속 팀
A9: 팀 | B9: 인원수 (명) | C9: 월 가용 M/M | D9: 연간 가용 M/M | E9: 연간 목표 수주액 (원) | F9: 연간 목표 이윤 (원) | P9: 1 | Q9: 홍길동 | R9: 사업운영팀 기획1파트
A10: 사업운영팀 기획1파트 | B10: 5 | C10: =IF($A10="",0,$B10*$B$4) -> 4.25 | D10: =IF($A10="",0,$C10*12) -> 51 | E10: 1000000000 | F10: 250000000 | P10: 2 | Q10: 김영수 | R10: 사업운영팀 기획1파트
A11: 사업운영팀 기획2파트 | B11: 4 | C11: =IF($A11="",0,$B11*$B$4) -> 3.4 | D11: =IF($A11="",0,$C11*12) -> 40.8 | E11: 500000000 | F11: 125000000 | P11: 3 | Q11: 박지은 | R11: 사업운영팀 기획1파트
A12: 신사업팀 | B12: 3 | C12: =IF($A12="",0,$B12*$B$4) -> 2.55 | D12: =IF($A12="",0,$C12*12) -> 30.6 | E12: 250000000 | F12: 62500000 | P12: 4 | Q12: 최민호 | R12: 사업운영팀 기획1파트
A13: 경영본부 사업기획실 | B13: 3 | C13: =IF($A13="",0,$B13*$B$4) -> 2.55 | D13: =IF($A13="",0,$C13*12) -> 30.6 | E13: 10000000 | F13: 2500000 | P13: 5 | Q13: 정수아 | R13: 사업운영팀 기획1파트
C14: =IF($A14="",0,$B14*$B$4) -> 0 | D14: =IF($A14="",0,$C14*12) -> 0 | P14: 6 | Q14: 김철수 | R14: 사업운영팀 기획2파트
C15: =IF($A15="",0,$B15*$B$4) -> 0 | D15: =IF($A15="",0,$C15*12) -> 0 | P15: 7 | Q15: 이하늘 | R15: 사업운영팀 기획2파트
C16: =IF($A16="",0,$B16*$B$4) -> 0 | D16: =IF($A16="",0,$C16*12) -> 0 | P16: 8 | Q16: 오세훈 | R16: 사업운영팀 기획2파트
C17: =IF($A17="",0,$B17*$B$4) -> 0 | D17: =IF($A17="",0,$C17*12) -> 0 | P17: 9 | Q17: 서정민 | R17: 사업운영팀 기획2파트
A18: 합계 | B18: =SUM(B10:B17) -> 15 | C18: =SUM(C10:C17) -> 12.75 | D18: =SUM(D10:D17) -> 153 | E18: =SUM(E10:E17) -> 1760000000 | F18: =SUM(F10:F17) | P18: 10 | Q18: 이영희 | R18: 신사업팀
A19: ※ 연간 목표 이윤: 경영진이 부여한 연간 이윤 목표. 목표가 없는 조직은 0으로 두세요. 지금 값은 목표 수주액의 25%로 채운 예시이니 실제 목표로 바꿔 주세요. | P19: 11 | Q19: 한지훈 | R19: 신사업팀
A20: ※ 연간 목표 수주액: 경영진이 부여한 연간 수주 목표. 목표가 없는 조직은 0으로 두세요. | P20: 12 | Q20: 문가영 | R20: 신사업팀
A21: ★ 팀 추가: 빈 슬롯(14~17행)에 팀명·인원수·목표만 입력하면 아래 모든 블록과 대시보드에 자동 반영됩니다. 다른 곳은 손대지 마세요. | P21: 13 | Q21: 박민수 | R21: 경영본부 사업기획실
A22: ② 팀별 월간 투입 M/M | P22: 14 | Q22: 윤소라 | R22: 경영본부 사업기획실
A23: 팀 | B23: =월간투입!E$7 -> 46023 | C23: =월간투입!F$7 -> 46054 | D23: =월간투입!G$7 -> 46082 | E23: =월간투입!H$7 -> 46113 | F23: =월간투입!I$7 -> 46143 | G23: =월간투입!J$7 -> 46174 | H23: =월간투입!K$7 -> 46204 | I23: =월간투입!L$7 -> 46235 | ... M23: =월간투입!P$7 -> 46357 | N23: 연간 합계 | P23: 15 | Q23: 강대현 | R23: 경영본부 사업기획실
A24: =IF($A10="","",$A10) -> 사업운영팀 기획1파트 | B24: =SUMIF(월간투입!$A$8:$A$127,$A24,월간투입!E$8:E$127) -> 5 | C24: =SUMIF(월간투입!$A$8:$A$127,$A24,월간투입!F$8:F$127) -> 5.2 | D24: =SUMIF(월간투입!$A$8:$A$127,$A24,월간투입!G$8:G$127) -> 5.4 | E24: =SUMIF(월간투입!$A$8:$A$127,$A24,월간투입!H$8:H$127) -> 5.3 | F24: =SUMIF(월간투입!$A$8:$A$127,$A24,월간투입!I$8:I$127) -> 5.1 | G24: =SUMIF(월간투입!$A$8:$A$127,$A24,월간투입!J$8:J$127) -> 3.7 | H24: =SUMIF(월간투입!$A$8:$A$127,$A24,월간투입!K$8:K$127) -> 3.7 | I24: =SUMIF(월간투입!$A$8:$A$127,$A24,월간투입!L$8:L$127) -> 3.9 | ... M24: =SUMIF(월간투입!$A$8:$A$127,$A24,월간투입!P$8:P$127) -> 3.9 | N24: =SUM(B24:M24) -> 52.9 | P24: 16
A25: =IF($A11="","",$A11) -> 사업운영팀 기획2파트 | B25: =SUMIF(월간투입!$A$8:$A$127,$A25,월간투입!E$8:E$127) -> 2.3 | C25: =SUMIF(월간투입!$A$8:$A$127,$A25,월간투입!F$8:F$127) -> 2.3 | D25: =SUMIF(월간투입!$A$8:$A$127,$A25,월간투입!G$8:G$127) -> 3.9 | E25: =SUMIF(월간투입!$A$8:$A$127,$A25,월간투입!H$8:H$127) -> 3.9 | F25: =SUMIF(월간투입!$A$8:$A$127,$A25,월간투입!I$8:I$127) -> 3.9 | G25: =SUMIF(월간투입!$A$8:$A$127,$A25,월간투입!J$8:J$127) -> 3.9 | H25: =SUMIF(월간투입!$A$8:$A$127,$A25,월간투입!K$8:K$127) -> 2.3 | I25: =SUMIF(월간투입!$A$8:$A$127,$A25,월간투입!L$8:L$127) -> 0.8 | ... M25: =SUMIF(월간투입!$A$8:$A$127,$A25,월간투입!P$8:P$127) -> 0.8 | N25: =SUM(B25:M25) -> 26.5 | P25: 17
A26: =IF($A12="","",$A12) -> 신사업팀 | B26: =SUMIF(월간투입!$A$8:$A$127,$A26,월간투입!E$8:E$127) -> 2.1 | C26: =SUMIF(월간투입!$A$8:$A$127,$A26,월간투입!F$8:F$127) -> 2.1 | D26: =SUMIF(월간투입!$A$8:$A$127,$A26,월간투입!G$8:G$127) -> 2.1 | E26: =SUMIF(월간투입!$A$8:$A$127,$A26,월간투입!H$8:H$127) -> 2.1 | F26: =SUMIF(월간투입!$A$8:$A$127,$A26,월간투입!I$8:I$127) -> 1.5 | G26: =SUMIF(월간투입!$A$8:$A$127,$A26,월간투입!J$8:J$127) -> 1.5 | H26: =SUMIF(월간투입!$A$8:$A$127,$A26,월간투입!K$8:K$127) -> 1.1 | I26: =SUMIF(월간투입!$A$8:$A$127,$A26,월간투입!L$8:L$127) -> 1.1 | ... M26: =SUMIF(월간투입!$A$8:$A$127,$A26,월간투입!P$8:P$127) -> 1.1 | N26: =SUM(B26:M26) -> 18 | P26: 18
A27: =IF($A13="","",$A13) -> 경영본부 사업기획실 | B27: =SUMIF(월간투입!$A$8:$A$127,$A27,월간투입!E$8:E$127) -> 2.2 | C27: =SUMIF(월간투입!$A$8:$A$127,$A27,월간투입!F$8:F$127) -> 2.2 | D27: =SUMIF(월간투입!$A$8:$A$127,$A27,월간투입!G$8:G$127) -> 2 | E27: =SUMIF(월간투입!$A$8:$A$127,$A27,월간투입!H$8:H$127) -> 2 | F27: =SUMIF(월간투입!$A$8:$A$127,$A27,월간투입!I$8:I$127) -> 2 | G27: =SUMIF(월간투입!$A$8:$A$127,$A27,월간투입!J$8:J$127) -> 2 | H27: =SUMIF(월간투입!$A$8:$A$127,$A27,월간투입!K$8:K$127) -> 2.2 | I27: =SUMIF(월간투입!$A$8:$A$127,$A27,월간투입!L$8:L$127) -> 2.2 | ... M27: =SUMIF(월간투입!$A$8:$A$127,$A27,월간투입!P$8:P$127) -> 2.9 | N27: =SUM(B27:M27) -> 27.6 | P27: 19
A28: =IF($A14="","",$A14) | B28: =SUMIF(월간투입!$A$8:$A$127,$A28,월간투입!E$8:E$127) -> 0 | C28: =SUMIF(월간투입!$A$8:$A$127,$A28,월간투입!F$8:F$127) -> 0 | D28: =SUMIF(월간투입!$A$8:$A$127,$A28,월간투입!G$8:G$127) -> 0 | E28: =SUMIF(월간투입!$A$8:$A$127,$A28,월간투입!H$8:H$127) -> 0 | F28: =SUMIF(월간투입!$A$8:$A$127,$A28,월간투입!I$8:I$127) -> 0 | G28: =SUMIF(월간투입!$A$8:$A$127,$A28,월간투입!J$8:J$127) -> 0 | H28: =SUMIF(월간투입!$A$8:$A$127,$A28,월간투입!K$8:K$127) -> 0 | I28: =SUMIF(월간투입!$A$8:$A$127,$A28,월간투입!L$8:L$127) -> 0 | ... M28: =SUMIF(월간투입!$A$8:$A$127,$A28,월간투입!P$8:P$127) -> 0 | N28: =SUM(B28:M28) -> 0 | P28: 20
A29: =IF($A15="","",$A15) | B29: =SUMIF(월간투입!$A$8:$A$127,$A29,월간투입!E$8:E$127) -> 0 | C29: =SUMIF(월간투입!$A$8:$A$127,$A29,월간투입!F$8:F$127) -> 0 | D29: =SUMIF(월간투입!$A$8:$A$127,$A29,월간투입!G$8:G$127) -> 0 | E29: =SUMIF(월간투입!$A$8:$A$127,$A29,월간투입!H$8:H$127) -> 0 | F29: =SUMIF(월간투입!$A$8:$A$127,$A29,월간투입!I$8:I$127) -> 0 | G29: =SUMIF(월간투입!$A$8:$A$127,$A29,월간투입!J$8:J$127) -> 0 | H29: =SUMIF(월간투입!$A$8:$A$127,$A29,월간투입!K$8:K$127) -> 0 | I29: =SUMIF(월간투입!$A$8:$A$127,$A29,월간투입!L$8:L$127) -> 0 | ... M29: =SUMIF(월간투입!$A$8:$A$127,$A29,월간투입!P$8:P$127) -> 0 | N29: =SUM(B29:M29) -> 0 | P29: 21
A30: =IF($A16="","",$A16) | B30: =SUMIF(월간투입!$A$8:$A$127,$A30,월간투입!E$8:E$127) -> 0 | C30: =SUMIF(월간투입!$A$8:$A$127,$A30,월간투입!F$8:F$127) -> 0 | D30: =SUMIF(월간투입!$A$8:$A$127,$A30,월간투입!G$8:G$127) -> 0 | E30: =SUMIF(월간투입!$A$8:$A$127,$A30,월간투입!H$8:H$127) -> 0 | F30: =SUMIF(월간투입!$A$8:$A$127,$A30,월간투입!I$8:I$127) -> 0 | G30: =SUMIF(월간투입!$A$8:$A$127,$A30,월간투입!J$8:J$127) -> 0 | H30: =SUMIF(월간투입!$A$8:$A$127,$A30,월간투입!K$8:K$127) -> 0 | I30: =SUMIF(월간투입!$A$8:$A$127,$A30,월간투입!L$8:L$127) -> 0 | ... M30: =SUMIF(월간투입!$A$8:$A$127,$A30,월간투입!P$8:P$127) -> 0 | N30: =SUM(B30:M30) -> 0 | P30: 22
A31: =IF($A17="","",$A17) | B31: =SUMIF(월간투입!$A$8:$A$127,$A31,월간투입!E$8:E$127) -> 0 | C31: =SUMIF(월간투입!$A$8:$A$127,$A31,월간투입!F$8:F$127) -> 0 | D31: =SUMIF(월간투입!$A$8:$A$127,$A31,월간투입!G$8:G$127) -> 0 | E31: =SUMIF(월간투입!$A$8:$A$127,$A31,월간투입!H$8:H$127) -> 0 | F31: =SUMIF(월간투입!$A$8:$A$127,$A31,월간투입!I$8:I$127) -> 0 | G31: =SUMIF(월간투입!$A$8:$A$127,$A31,월간투입!J$8:J$127) -> 0 | H31: =SUMIF(월간투입!$A$8:$A$127,$A31,월간투입!K$8:K$127) -> 0 | I31: =SUMIF(월간투입!$A$8:$A$127,$A31,월간투입!L$8:L$127) -> 0 | ... M31: =SUMIF(월간투입!$A$8:$A$127,$A31,월간투입!P$8:P$127) -> 0 | N31: =SUM(B31:M31) -> 0 | P31: 23
P32: 24
P33: 25
A34: ③ 팀별 월간 가동률 (투입 ÷ 가용) | P34: 26
A35: 진한 빨강 = 120% 초과(심각) · 주황 = 100~120%(주의) · 초록 = 70% 미만(여력 있음) | P35: 27
A36: 팀 | B36: =월간투입!E$7 -> 46023 | C36: =월간투입!F$7 -> 46054 | D36: =월간투입!G$7 -> 46082 | E36: =월간투입!H$7 -> 46113 | F36: =월간투입!I$7 -> 46143 | G36: =월간투입!J$7 -> 46174 | H36: =월간투입!K$7 -> 46204 | I36: =월간투입!L$7 -> 46235 | ... M36: =월간투입!P$7 -> 46357 | N36: 평균 | P36: 28
A37: =IF($A10="","",$A10) -> 사업운영팀 기획1파트 | B37: =IF($C$10=0,"",B24/$C$10) -> 1.1764706 | C37: =IF($C$10=0,"",C24/$C$10) -> 1.2235294 | D37: =IF($C$10=0,"",D24/$C$10) -> 1.2705882 | E37: =IF($C$10=0,"",E24/$C$10) -> 1.2470588 | F37: =IF($C$10=0,"",F24/$C$10) -> 1.2 | G37: =IF($C$10=0,"",G24/$C$10) -> 0.87058824 | H37: =IF($C$10=0,"",H24/$C$10) -> 0.87058824 | I37: =IF($C$10=0,"",I24/$C$10) -> 0.91764706 | ... M37: =IF($C$10=0,"",M24/$C$10) -> 0.91764706 | N37: =IF($D$10=0,"",N24/$D$10) -> 1.0372549 | P37: 29
A38: =IF($A11="","",$A11) -> 사업운영팀 기획2파트 | B38: =IF($C$11=0,"",B25/$C$11) -> 0.67647059 | C38: =IF($C$11=0,"",C25/$C$11) -> 0.67647059 | D38: =IF($C$11=0,"",D25/$C$11) -> 1.1470588 | E38: =IF($C$11=0,"",E25/$C$11) -> 1.1470588 | F38: =IF($C$11=0,"",F25/$C$11) -> 1.1470588 | G38: =IF($C$11=0,"",G25/$C$11) -> 1.1470588 | H38: =IF($C$11=0,"",H25/$C$11) -> 0.67647059 | I38: =IF($C$11=0,"",I25/$C$11) -> 0.23529412 | ... M38: =IF($C$11=0,"",M25/$C$11) -> 0.23529412 | N38: =IF($D$11=0,"",N25/$D$11) -> 0.6495098 | P38: 30
A39: =IF($A12="","",$A12) -> 신사업팀 | B39: =IF($C$12=0,"",B26/$C$12) -> 0.82352941 | C39: =IF($C$12=0,"",C26/$C$12) -> 0.82352941 | D39: =IF($C$12=0,"",D26/$C$12) -> 0.82352941 | E39: =IF($C$12=0,"",E26/$C$12) -> 0.82352941 | F39: =IF($C$12=0,"",F26/$C$12) -> 0.58823529 | G39: =IF($C$12=0,"",G26/$C$12) -> 0.58823529 | H39: =IF($C$12=0,"",H26/$C$12) -> 0.43137255 | I39: =IF($C$12=0,"",I26/$C$12) -> 0.43137255 | ... M39: =IF($C$12=0,"",M26/$C$12) -> 0.43137255 | N39: =IF($D$12=0,"",N26/$D$12) -> 0.58823529 | P39: 31
A40: =IF($A13="","",$A13) -> 경영본부 사업기획실 | B40: =IF($C$13=0,"",B27/$C$13) -> 0.8627451 | C40: =IF($C$13=0,"",C27/$C$13) -> 0.8627451 | D40: =IF($C$13=0,"",D27/$C$13) -> 0.78431373 | E40: =IF($C$13=0,"",E27/$C$13) -> 0.78431373 | F40: =IF($C$13=0,"",F27/$C$13) -> 0.78431373 | G40: =IF($C$13=0,"",G27/$C$13) -> 0.78431373 | H40: =IF($C$13=0,"",H27/$C$13) -> 0.8627451 | I40: =IF($C$13=0,"",I27/$C$13) -> 0.8627451 | ... M40: =IF($C$13=0,"",M27/$C$13) -> 1.1372549 | N40: =IF($D$13=0,"",N27/$D$13) -> 0.90196078 | P40: 32
A41: =IF($A14="","",$A14) | B41: =IF($C$14=0,"",B28/$C$14) | C41: =IF($C$14=0,"",C28/$C$14) | D41: =IF($C$14=0,"",D28/$C$14) | E41: =IF($C$14=0,"",E28/$C$14) | F41: =IF($C$14=0,"",F28/$C$14) | G41: =IF($C$14=0,"",G28/$C$14) | H41: =IF($C$14=0,"",H28/$C$14) | I41: =IF($C$14=0,"",I28/$C$14) | ... M41: =IF($C$14=0,"",M28/$C$14) | N41: =IF($D$14=0,"",N28/$D$14) | P41: 33
...

Sheet 상세현황
A1: 팀별 상세 현황
A2: 월별 상세 수치와 팀별 요약표. 요약은 대시보드 시트를 보세요.
A4: 전사 평균 가동률 | D4: 연간 여유 M/M | G4: 확정 수주 (원) | J4: 귀속 이윤 (원) | M4: 수주 달성률 | P4: 기간 진도율
A5: =IF(팀별분석!D18=0,"",팀별분석!B69/팀별분석!D18) -> 0.81699346 | D5: =팀별분석!D18-팀별분석!B69 -> 28 | G5: =팀별분석!D69 -> 1640000000 | J5: =팀별분석!E69 -> 448000000 | M5: =팀별분석!J69 -> 0.93181818 | P5: =팀별분석!$B$6 -> 0.66666667
A73: 팀별 요약
A74: 팀 | B74: 평균 가동률 | C74: 과부하 월수 | D74: 연간 여유 M/M | E74: 확정 수주 (원) | F74: 목표 수주액 (원) | G74: 수주 달성률 | H74: 진도 차이 | I74: 컨디션 판정 | J74: 수주 판정
A75: =팀별분석!A74 -> 사업운영팀 기획1파트 | B75: =팀별분석!B74 -> 1.0372549 | C75: =팀별분석!D74 -> 5 | D75: =팀별분석!E74 -> -1.9 | E75: =팀별분석!D61 -> 990000000 | F75: =팀별분석!I61 -> 1000000000 | G75: =팀별분석!J61 -> 0.99 | H75: =팀별분석!L61 -> 0.32333333 | I75: =팀별분석!I74 -> 과부하 | J75: =팀별분석!J74 -> 진도 앞섬
A76: =팀별분석!A75 -> 사업운영팀 기획2파트 | B76: =팀별분석!B75 -> 0.6495098 | C76: =팀별분석!D75 -> 4 | D76: =팀별분석!E75 -> 14.3 | E76: =팀별분석!D62 -> 430000000 | F76: =팀별분석!I62 -> 500000000 | G76: =팀별분석!J62 -> 0.86 | H76: =팀별분석!L62 -> 0.19333333 | I76: =팀별분석!I75 -> 여력 있음 | J76: =팀별분석!J75 -> 진도 앞섬
A77: =팀별분석!A76 -> 신사업팀 | B77: =팀별분석!B76 -> 0.58823529 | C77: =팀별분석!D76 -> 0 | D77: =팀별분석!E76 -> 12.6 | E77: =팀별분석!D63 -> 1.2810811e+08 | F77: =팀별분석!I63 -> 250000000 | G77: =팀별분석!J63 -> 0.51243243 | H77: =팀별분석!L63 -> -0.15423423 | I77: =팀별분석!I76 -> 여력 있음 | J77: =팀별분석!J76 -> 진도 지연
A78: =팀별분석!A77 -> 경영본부 사업기획실 | B78: =팀별분석!B77 -> 0.90196078 | C78: =팀별분석!D77 -> 3 | D78: =팀별분석!E77 -> 3 | E78: =팀별분석!D64 -> 91891892 | F78: =팀별분석!I64 -> 10000000 | G78: =팀별분석!J64 -> 9.1891892 | H78: =팀별분석!L64 -> 8.5225225 | I78: =팀별분석!I77 -> 여유 없음 | J78: =팀별분석!J77 -> 진도 앞섬
A79: =팀별분석!A78 | B79: =팀별분석!B78 | C79: =팀별분석!D78 -> 0 | D79: =팀별분석!E78 -> 0 | E79: =팀별분석!D65 -> 0 | F79: =팀별분석!I65 -> 0 | G79: =팀별분석!J65 | H79: =팀별분석!L65 | I79: =팀별분석!I78 | J79: =팀별분석!J78
A80: ※ 여력 있는 팀 + 진도 지연 팀 조합이 업무 재배분 대상입니다. | B80: =팀별분석!B79 | C80: =팀별분석!D79 -> 0 | D80: =팀별분석!E79 -> 0 | E80: =팀별분석!D66 -> 0 | F80: =팀별분석!I66 -> 0 | G80: =팀별분석!J66 | H80: =팀별분석!L66 | I80: =팀별분석!I79 | J80: =팀별분석!J79
A81: ※ 수주 판정은 기간 진도율 대비입니다. 기준월(팀별분석 B5)을 매달 갱신하세요. | B81: =팀별분석!B80 | C81: =팀별분석!D80 -> 0 | D81: =팀별분석!E80 -> 0 | E81: =팀별분석!D67 -> 0 | F81: =팀별분석!I67 -> 0 | G81: =팀별분석!J67 | H81: =팀별분석!L67 | I81: =팀별분석!I80 | J81: =팀별분석!J80
A82: =팀별분석!A81 | B82: =팀별분석!B81 | C82: =팀별분석!D81 -> 0 | D82: =팀별분석!E81 -> 0 | E82: =팀별분석!D68 -> 0 | F82: =팀별분석!I68 -> 0 | G82: =팀별분석!J68 | H82: =팀별분석!L68 | I82: =팀별분석!I81 | J82: =팀별분석!J81
A90: [차트 보조 데이터] 지우지 마세요
A91: 팀 | B91: 연간 가용 M/M | C91: 연간 투입 M/M | E91: 팀 | F91: 목표 수주액 | G91: 확정 수주 | I91: 팀 | J91: M/M당 예산 | K91: M/M당 이윤
A92: =팀별분석!A10 -> 사업운영팀 기획1파트 | B92: =팀별분석!D10 -> 51 | C92: =팀별분석!N24 -> 52.9 | E92: =팀별분석!A10 -> 사업운영팀 기획1파트 | F92: =팀별분석!I61 -> 1000000000 | G92: =팀별분석!D61 -> 990000000 | I92: =팀별분석!A10 -> 사업운영팀 기획1파트 | J92: =팀별분석!G61 -> 34982332 | K92: =팀별분석!H61 -> 10318021
A93: =팀별분석!A11 -> 사업운영팀 기획2파트 | B93: =팀별분석!D11 -> 40.8 | C93: =팀별분석!N25 -> 26.5 | E93: =팀별분석!A11 -> 사업운영팀 기획2파트 | F93: =팀별분석!I62 -> 500000000 | G93: =팀별분석!D62 -> 430000000 | I93: =팀별분석!A11 -> 사업운영팀 기획2파트 | J93: =팀별분석!G62 -> 21938776 | K93: =팀별분석!H62 -> 5918367.3
A94: =팀별분석!A12 -> 신사업팀 | B94: =팀별분석!D12 -> 30.6 | C94: =팀별분석!N26 -> 18 | E94: =팀별분석!A12 -> 신사업팀 | F94: =팀별분석!I63 -> 250000000 | G94: =팀별분석!D63 -> 1.2810811e+08 | I94: =팀별분석!A12 -> 신사업팀 | J94: =팀별분석!G63 -> 8212058.2 | K94: =팀별분석!H63 -> 1642411.6
A95: =팀별분석!A13 -> 경영본부 사업기획실 | B95: =팀별분석!D13 -> 30.6 | C95: =팀별분석!N27 -> 27.6 | E95: =팀별분석!A13 -> 경영본부 사업기획실 | F95: =팀별분석!I64 -> 10000000 | G95: =팀별분석!D64 -> 91891892 | I95: =팀별분석!A13 -> 경영본부 사업기획실 | J95: =팀별분석!G64 -> 6381381.4 | K95: =팀별분석!H64 -> 998498.5
A96: =팀별분석!A14 -> 0 | B96: =팀별분석!D14 -> 0 | C96: =팀별분석!N28 -> 0 | E96: =팀별분석!A14 -> 0 | F96: =팀별분석!I65 -> 0 | G96: =팀별분석!D65 -> 0 | I96: =팀별분석!A14 -> 0 | J96: =팀별분석!G65 | K96: =팀별분석!H65
A97: =팀별분석!A15 -> 0 | B97: =팀별분석!D15 -> 0 | C97: =팀별분석!N29 -> 0 | E97: =팀별분석!A15 -> 0 | F97: =팀별분석!I66 -> 0 | G97: =팀별분석!D66 -> 0 | I97: =팀별분석!A15 -> 0 | J97: =팀별분석!G66 | K97: =팀별분석!H66
A98: =팀별분석!A16 -> 0 | B98: =팀별분석!D16 -> 0 | C98: =팀별분석!N30 -> 0 | E98: =팀별분석!A16 -> 0 | F98: =팀별분석!I67 -> 0 | G98: =팀별분석!D67 -> 0 | I98: =팀별분석!A16 -> 0 | J98: =팀별분석!G67 | K98: =팀별분석!H67
A99: =팀별분석!A17 -> 0 | B99: =팀별분석!D17 -> 0 | C99: =팀별분석!N31 -> 0 | E99: =팀별분석!A17 -> 0 | F99: =팀별분석!I68 -> 0 | G99: =팀별분석!D68 -> 0 | I99: =팀별분석!A17 -> 0 | J99: =팀별분석!G68 | K99: =팀별분석!H68
